# Pavilhao curvo direito: espelho exato do esquerdo.
# GERADO por tools/gen_castle.py; nao editar a mao.
fill ~21 ~0 ~8 ~21 ~0 ~9 minecraft:smooth_quartz
fill ~21 ~1 ~8 ~21 ~1 ~9 minecraft:smooth_quartz
fill ~21 ~5 ~8 ~21 ~5 ~9 minecraft:smooth_quartz
fill ~21 ~9 ~8 ~21 ~9 ~9 minecraft:smooth_quartz
fill ~21 ~10 ~8 ~21 ~10 ~9 minecraft:smooth_quartz
setblock ~21 ~1 ~8 minecraft:chiseled_quartz_block
setblock ~21 ~5 ~8 minecraft:chiseled_quartz_block
setblock ~21 ~9 ~8 minecraft:chiseled_quartz_block
setblock ~21 ~10 ~7 minecraft:quartz_stairs[facing=south,half=top]
fill ~21 ~2 ~8 ~21 ~4 ~8 minecraft:quartz_pillar[axis=y]
fill ~21 ~6 ~8 ~21 ~8 ~8 minecraft:quartz_pillar[axis=y]
setblock ~21 ~11 ~8 minecraft:chiseled_quartz_block
fill ~20 ~0 ~7 ~20 ~0 ~8 minecraft:smooth_quartz
fill ~20 ~1 ~7 ~20 ~1 ~8 minecraft:smooth_quartz
fill ~20 ~5 ~7 ~20 ~5 ~8 minecraft:smooth_quartz
fill ~20 ~9 ~7 ~20 ~9 ~8 minecraft:smooth_quartz
fill ~20 ~10 ~7 ~20 ~10 ~8 minecraft:smooth_quartz
setblock ~20 ~1 ~7 minecraft:chiseled_quartz_block
setblock ~20 ~5 ~7 minecraft:chiseled_quartz_block
setblock ~20 ~9 ~7 minecraft:chiseled_quartz_block
setblock ~20 ~10 ~6 minecraft:quartz_stairs[facing=south,half=top]
setblock ~20 ~2 ~7 minecraft:diorite_wall
setblock ~20 ~6 ~7 minecraft:diorite_wall
fill ~19 ~0 ~6 ~19 ~0 ~7 minecraft:smooth_quartz
fill ~19 ~1 ~6 ~19 ~1 ~7 minecraft:smooth_quartz
fill ~19 ~5 ~6 ~19 ~5 ~7 minecraft:smooth_quartz
fill ~19 ~9 ~6 ~19 ~9 ~7 minecraft:smooth_quartz
fill ~19 ~10 ~6 ~19 ~10 ~7 minecraft:smooth_quartz
setblock ~19 ~1 ~6 minecraft:chiseled_quartz_block
setblock ~19 ~5 ~6 minecraft:chiseled_quartz_block
setblock ~19 ~9 ~6 minecraft:chiseled_quartz_block
setblock ~19 ~10 ~5 minecraft:quartz_stairs[facing=south,half=top]
setblock ~19 ~2 ~6 minecraft:diorite_wall
setblock ~19 ~6 ~6 minecraft:diorite_wall
fill ~18 ~0 ~6 ~18 ~0 ~7 minecraft:smooth_quartz
fill ~18 ~1 ~6 ~18 ~1 ~7 minecraft:smooth_quartz
fill ~18 ~5 ~6 ~18 ~5 ~7 minecraft:smooth_quartz
fill ~18 ~9 ~6 ~18 ~9 ~7 minecraft:smooth_quartz
fill ~18 ~10 ~6 ~18 ~10 ~7 minecraft:smooth_quartz
setblock ~18 ~1 ~6 minecraft:chiseled_quartz_block
setblock ~18 ~5 ~6 minecraft:chiseled_quartz_block
setblock ~18 ~9 ~6 minecraft:chiseled_quartz_block
setblock ~18 ~10 ~5 minecraft:quartz_stairs[facing=south,half=top]
fill ~18 ~2 ~6 ~18 ~4 ~6 minecraft:quartz_pillar[axis=y]
fill ~18 ~6 ~6 ~18 ~8 ~6 minecraft:quartz_pillar[axis=y]
fill ~17 ~0 ~5 ~17 ~0 ~6 minecraft:smooth_quartz
fill ~17 ~1 ~5 ~17 ~1 ~6 minecraft:smooth_quartz
fill ~17 ~5 ~5 ~17 ~5 ~6 minecraft:smooth_quartz
fill ~17 ~9 ~5 ~17 ~9 ~6 minecraft:smooth_quartz
fill ~17 ~10 ~5 ~17 ~10 ~6 minecraft:smooth_quartz
setblock ~17 ~1 ~5 minecraft:chiseled_quartz_block
setblock ~17 ~5 ~5 minecraft:chiseled_quartz_block
setblock ~17 ~9 ~5 minecraft:chiseled_quartz_block
setblock ~17 ~10 ~4 minecraft:quartz_stairs[facing=south,half=top]
setblock ~17 ~2 ~5 minecraft:diorite_wall
setblock ~17 ~6 ~5 minecraft:diorite_wall
fill ~16 ~0 ~5 ~16 ~0 ~6 minecraft:smooth_quartz
fill ~16 ~1 ~5 ~16 ~1 ~6 minecraft:smooth_quartz
fill ~16 ~5 ~5 ~16 ~5 ~6 minecraft:smooth_quartz
fill ~16 ~9 ~5 ~16 ~9 ~6 minecraft:smooth_quartz
fill ~16 ~10 ~5 ~16 ~10 ~6 minecraft:smooth_quartz
setblock ~16 ~1 ~5 minecraft:chiseled_quartz_block
setblock ~16 ~5 ~5 minecraft:chiseled_quartz_block
setblock ~16 ~9 ~5 minecraft:chiseled_quartz_block
setblock ~16 ~10 ~4 minecraft:quartz_stairs[facing=south,half=top]
setblock ~16 ~2 ~5 minecraft:diorite_wall
setblock ~16 ~6 ~5 minecraft:diorite_wall
fill ~15 ~0 ~5 ~15 ~0 ~6 minecraft:smooth_quartz
fill ~15 ~1 ~5 ~15 ~1 ~6 minecraft:smooth_quartz
fill ~15 ~5 ~5 ~15 ~5 ~6 minecraft:smooth_quartz
fill ~15 ~9 ~5 ~15 ~9 ~6 minecraft:smooth_quartz
fill ~15 ~10 ~5 ~15 ~10 ~6 minecraft:smooth_quartz
setblock ~15 ~1 ~5 minecraft:chiseled_quartz_block
setblock ~15 ~5 ~5 minecraft:chiseled_quartz_block
setblock ~15 ~9 ~5 minecraft:chiseled_quartz_block
setblock ~15 ~10 ~4 minecraft:quartz_stairs[facing=south,half=top]
fill ~15 ~2 ~5 ~15 ~4 ~5 minecraft:quartz_pillar[axis=y]
fill ~15 ~6 ~5 ~15 ~8 ~5 minecraft:quartz_pillar[axis=y]
fill ~14 ~0 ~5 ~14 ~0 ~6 minecraft:smooth_quartz
fill ~14 ~1 ~5 ~14 ~1 ~6 minecraft:smooth_quartz
fill ~14 ~5 ~5 ~14 ~5 ~6 minecraft:smooth_quartz
fill ~14 ~9 ~5 ~14 ~9 ~6 minecraft:smooth_quartz
fill ~14 ~10 ~5 ~14 ~10 ~6 minecraft:smooth_quartz
setblock ~14 ~1 ~5 minecraft:chiseled_quartz_block
setblock ~14 ~5 ~5 minecraft:chiseled_quartz_block
setblock ~14 ~9 ~5 minecraft:chiseled_quartz_block
setblock ~14 ~10 ~4 minecraft:quartz_stairs[facing=south,half=top]
setblock ~14 ~2 ~5 minecraft:diorite_wall
setblock ~14 ~6 ~5 minecraft:diorite_wall
fill ~13 ~0 ~5 ~13 ~0 ~6 minecraft:smooth_quartz
fill ~13 ~1 ~5 ~13 ~1 ~6 minecraft:smooth_quartz
fill ~13 ~5 ~5 ~13 ~5 ~6 minecraft:smooth_quartz
fill ~13 ~9 ~5 ~13 ~9 ~6 minecraft:smooth_quartz
fill ~13 ~10 ~5 ~13 ~10 ~6 minecraft:smooth_quartz
setblock ~13 ~1 ~5 minecraft:chiseled_quartz_block
setblock ~13 ~5 ~5 minecraft:chiseled_quartz_block
setblock ~13 ~9 ~5 minecraft:chiseled_quartz_block
setblock ~13 ~10 ~4 minecraft:quartz_stairs[facing=south,half=top]
setblock ~13 ~2 ~5 minecraft:diorite_wall
setblock ~13 ~6 ~5 minecraft:diorite_wall
fill ~12 ~0 ~6 ~12 ~0 ~7 minecraft:smooth_quartz
fill ~12 ~1 ~6 ~12 ~1 ~7 minecraft:smooth_quartz
fill ~12 ~5 ~6 ~12 ~5 ~7 minecraft:smooth_quartz
fill ~12 ~9 ~6 ~12 ~9 ~7 minecraft:smooth_quartz
fill ~12 ~10 ~6 ~12 ~10 ~7 minecraft:smooth_quartz
setblock ~12 ~1 ~6 minecraft:chiseled_quartz_block
setblock ~12 ~5 ~6 minecraft:chiseled_quartz_block
setblock ~12 ~9 ~6 minecraft:chiseled_quartz_block
setblock ~12 ~10 ~5 minecraft:quartz_stairs[facing=south,half=top]
fill ~12 ~2 ~6 ~12 ~4 ~6 minecraft:quartz_pillar[axis=y]
fill ~12 ~6 ~6 ~12 ~8 ~6 minecraft:quartz_pillar[axis=y]
fill ~11 ~0 ~6 ~11 ~0 ~7 minecraft:smooth_quartz
fill ~11 ~1 ~6 ~11 ~1 ~7 minecraft:smooth_quartz
fill ~11 ~5 ~6 ~11 ~5 ~7 minecraft:smooth_quartz
fill ~11 ~9 ~6 ~11 ~9 ~7 minecraft:smooth_quartz
fill ~11 ~10 ~6 ~11 ~10 ~7 minecraft:smooth_quartz
setblock ~11 ~1 ~6 minecraft:chiseled_quartz_block
setblock ~11 ~5 ~6 minecraft:chiseled_quartz_block
setblock ~11 ~9 ~6 minecraft:chiseled_quartz_block
setblock ~11 ~10 ~5 minecraft:quartz_stairs[facing=south,half=top]
setblock ~11 ~2 ~6 minecraft:diorite_wall
setblock ~11 ~6 ~6 minecraft:diorite_wall
fill ~10 ~0 ~7 ~10 ~0 ~8 minecraft:smooth_quartz
fill ~10 ~1 ~7 ~10 ~1 ~8 minecraft:smooth_quartz
fill ~10 ~5 ~7 ~10 ~5 ~8 minecraft:smooth_quartz
fill ~10 ~9 ~7 ~10 ~9 ~8 minecraft:smooth_quartz
fill ~10 ~10 ~7 ~10 ~10 ~8 minecraft:smooth_quartz
setblock ~10 ~1 ~7 minecraft:chiseled_quartz_block
setblock ~10 ~5 ~7 minecraft:chiseled_quartz_block
setblock ~10 ~9 ~7 minecraft:chiseled_quartz_block
setblock ~10 ~10 ~6 minecraft:quartz_stairs[facing=south,half=top]
setblock ~10 ~2 ~7 minecraft:diorite_wall
setblock ~10 ~6 ~7 minecraft:diorite_wall
fill ~9 ~0 ~8 ~9 ~0 ~9 minecraft:smooth_quartz
fill ~9 ~1 ~8 ~9 ~1 ~9 minecraft:smooth_quartz
fill ~9 ~5 ~8 ~9 ~5 ~9 minecraft:smooth_quartz
fill ~9 ~9 ~8 ~9 ~9 ~9 minecraft:smooth_quartz
fill ~9 ~10 ~8 ~9 ~10 ~9 minecraft:smooth_quartz
setblock ~9 ~1 ~8 minecraft:chiseled_quartz_block
setblock ~9 ~5 ~8 minecraft:chiseled_quartz_block
setblock ~9 ~9 ~8 minecraft:chiseled_quartz_block
setblock ~9 ~10 ~7 minecraft:quartz_stairs[facing=south,half=top]
fill ~9 ~2 ~8 ~9 ~4 ~8 minecraft:quartz_pillar[axis=y]
fill ~9 ~6 ~8 ~9 ~8 ~8 minecraft:quartz_pillar[axis=y]
setblock ~9 ~11 ~8 minecraft:chiseled_quartz_block
fill ~19 ~1 ~8 ~19 ~1 ~8 minecraft:polished_blackstone
fill ~19 ~5 ~8 ~19 ~5 ~8 minecraft:polished_blackstone
fill ~18 ~1 ~8 ~18 ~1 ~8 minecraft:polished_blackstone
fill ~18 ~5 ~8 ~18 ~5 ~8 minecraft:polished_blackstone
fill ~17 ~1 ~7 ~17 ~1 ~8 minecraft:polished_blackstone
fill ~17 ~5 ~7 ~17 ~5 ~8 minecraft:polished_blackstone
fill ~16 ~1 ~7 ~16 ~1 ~8 minecraft:polished_blackstone
fill ~16 ~5 ~7 ~16 ~5 ~8 minecraft:polished_blackstone
fill ~15 ~1 ~7 ~15 ~1 ~8 minecraft:polished_blackstone
fill ~15 ~5 ~7 ~15 ~5 ~8 minecraft:polished_blackstone
fill ~14 ~1 ~7 ~14 ~1 ~8 minecraft:polished_blackstone
fill ~14 ~5 ~7 ~14 ~5 ~8 minecraft:polished_blackstone
fill ~13 ~1 ~7 ~13 ~1 ~8 minecraft:polished_blackstone
fill ~13 ~5 ~7 ~13 ~5 ~8 minecraft:polished_blackstone
fill ~12 ~1 ~8 ~12 ~1 ~8 minecraft:polished_blackstone
fill ~12 ~5 ~8 ~12 ~5 ~8 minecraft:polished_blackstone
fill ~11 ~1 ~8 ~11 ~1 ~8 minecraft:polished_blackstone
fill ~11 ~5 ~8 ~11 ~5 ~8 minecraft:polished_blackstone
fill ~18 ~2 ~8 ~18 ~8 ~8 minecraft:polished_blackstone_wall
fill ~15 ~2 ~8 ~15 ~8 ~8 minecraft:polished_blackstone_wall
fill ~12 ~2 ~8 ~12 ~8 ~8 minecraft:polished_blackstone_wall
fill ~10 ~0 ~9 ~20 ~9 ~9 minecraft:polished_blackstone
fill ~21 ~0 ~9 ~21 ~10 ~9 minecraft:smooth_quartz
fill ~8 ~0 ~8 ~8 ~10 ~9 minecraft:smooth_quartz
