# Arco central: ombreiras, pilastras, brasao e cortina de fios.
# GERADO por tools/gen_castle.py; nao editar a mao.
fill ~-7 ~0 ~9 ~-5 ~10 ~11 minecraft:smooth_quartz
fill ~5 ~0 ~9 ~7 ~10 ~11 minecraft:smooth_quartz
setblock ~-6 ~0 ~8 minecraft:chiseled_quartz_block
fill ~-6 ~1 ~8 ~-6 ~8 ~8 minecraft:quartz_pillar[axis=y]
setblock ~-6 ~9 ~8 minecraft:chiseled_quartz_block
setblock ~6 ~0 ~8 minecraft:chiseled_quartz_block
fill ~6 ~1 ~8 ~6 ~8 ~8 minecraft:quartz_pillar[axis=y]
setblock ~6 ~9 ~8 minecraft:chiseled_quartz_block
fill ~-5 ~0 ~9 ~-5 ~9 ~9 minecraft:chiseled_quartz_block
fill ~5 ~0 ~9 ~5 ~9 ~9 minecraft:chiseled_quartz_block
fill ~-4 ~10 ~9 ~4 ~10 ~11 minecraft:smooth_quartz
fill ~-4 ~10 ~9 ~4 ~10 ~9 minecraft:chiseled_quartz_block
setblock ~-4 ~9 ~9 minecraft:quartz_stairs[facing=west,half=top]
setblock ~4 ~9 ~9 minecraft:quartz_stairs[facing=east,half=top]
fill ~-8 ~11 ~9 ~8 ~11 ~11 minecraft:smooth_quartz
fill ~-8 ~11 ~9 ~8 ~11 ~9 minecraft:chiseled_quartz_block
fill ~-8 ~12 ~9 ~8 ~12 ~11 minecraft:smooth_quartz
fill ~-8 ~12 ~8 ~8 ~12 ~8 minecraft:quartz_stairs[facing=south,half=top]
fill ~-3 ~13 ~9 ~3 ~13 ~10 minecraft:smooth_quartz
fill ~-1 ~14 ~9 ~1 ~15 ~9 minecraft:gold_block
setblock ~-2 ~14 ~9 minecraft:chiseled_quartz_block
setblock ~2 ~14 ~9 minecraft:chiseled_quartz_block
setblock ~-3 ~14 ~9 minecraft:quartz_stairs[facing=east,half=bottom]
setblock ~3 ~14 ~9 minecraft:quartz_stairs[facing=west,half=bottom]
setblock ~0 ~16 ~9 minecraft:chiseled_quartz_block
fill ~-4 ~0 ~10 ~-4 ~8 ~10 minecraft:white_stained_glass_pane
fill ~-2 ~0 ~10 ~-2 ~8 ~10 minecraft:white_stained_glass_pane
fill ~0 ~0 ~10 ~0 ~8 ~10 minecraft:white_stained_glass_pane
fill ~2 ~0 ~10 ~2 ~8 ~10 minecraft:white_stained_glass_pane
fill ~4 ~0 ~10 ~4 ~8 ~10 minecraft:white_stained_glass_pane
fill ~-5 ~0 ~12 ~5 ~10 ~12 minecraft:black_concrete
