# Pavilhao curvo direito: espelho exato do esquerdo.
# GERADO por tools/gen_castle.py; nao editar a mao.
fill ~64 ~0 ~26 ~64 ~4 ~27 minecraft:smooth_quartz
fill ~64 ~2 ~26 ~64 ~3 ~26 minecraft:chiseled_quartz_block
setblock ~64 ~5 ~26 minecraft:smooth_quartz
setblock ~64 ~5 ~27 minecraft:smooth_quartz
setblock ~64 ~5 ~25 minecraft:quartz_stairs[facing=south,half=top]
fill ~64 ~15 ~26 ~64 ~17 ~27 minecraft:smooth_quartz
setblock ~64 ~16 ~26 minecraft:chiseled_quartz_block
setblock ~64 ~15 ~25 minecraft:quartz_stairs[facing=south,half=bottom]
setblock ~64 ~17 ~25 minecraft:quartz_stairs[facing=south,half=top]
fill ~64 ~18 ~26 ~64 ~20 ~27 minecraft:smooth_quartz
setblock ~64 ~19 ~26 minecraft:chiseled_quartz_block
setblock ~64 ~21 ~26 minecraft:smooth_quartz
setblock ~64 ~21 ~27 minecraft:smooth_quartz
setblock ~64 ~21 ~25 minecraft:quartz_stairs[facing=south,half=top]
fill ~64 ~30 ~26 ~64 ~32 ~27 minecraft:smooth_quartz
setblock ~64 ~31 ~26 minecraft:chiseled_quartz_block
setblock ~64 ~33 ~26 minecraft:smooth_quartz
setblock ~64 ~33 ~27 minecraft:smooth_quartz
setblock ~64 ~33 ~25 minecraft:quartz_stairs[facing=south,half=top]
setblock ~64 ~34 ~26 minecraft:quartz_slab[type=bottom]
fill ~63 ~0 ~24 ~63 ~4 ~25 minecraft:smooth_quartz
fill ~63 ~2 ~24 ~63 ~3 ~24 minecraft:chiseled_quartz_block
setblock ~63 ~5 ~24 minecraft:smooth_quartz
setblock ~63 ~5 ~25 minecraft:smooth_quartz
setblock ~63 ~5 ~23 minecraft:quartz_stairs[facing=south,half=top]
fill ~63 ~15 ~24 ~63 ~17 ~25 minecraft:smooth_quartz
setblock ~63 ~16 ~24 minecraft:chiseled_quartz_block
setblock ~63 ~15 ~23 minecraft:quartz_stairs[facing=south,half=bottom]
setblock ~63 ~17 ~23 minecraft:quartz_stairs[facing=south,half=top]
fill ~63 ~18 ~24 ~63 ~20 ~25 minecraft:smooth_quartz
setblock ~63 ~19 ~24 minecraft:chiseled_quartz_block
setblock ~63 ~21 ~24 minecraft:smooth_quartz
setblock ~63 ~21 ~25 minecraft:smooth_quartz
setblock ~63 ~21 ~23 minecraft:quartz_stairs[facing=south,half=top]
fill ~63 ~30 ~24 ~63 ~32 ~25 minecraft:smooth_quartz
setblock ~63 ~31 ~24 minecraft:chiseled_quartz_block
setblock ~63 ~33 ~24 minecraft:smooth_quartz
setblock ~63 ~33 ~25 minecraft:smooth_quartz
setblock ~63 ~33 ~23 minecraft:quartz_stairs[facing=south,half=top]
setblock ~63 ~34 ~24 minecraft:quartz_slab[type=bottom]
fill ~62 ~0 ~23 ~62 ~4 ~24 minecraft:smooth_quartz
fill ~62 ~2 ~23 ~62 ~3 ~23 minecraft:chiseled_quartz_block
setblock ~62 ~5 ~23 minecraft:smooth_quartz
setblock ~62 ~5 ~24 minecraft:smooth_quartz
setblock ~62 ~5 ~22 minecraft:quartz_stairs[facing=south,half=top]
fill ~62 ~15 ~23 ~62 ~17 ~24 minecraft:smooth_quartz
setblock ~62 ~16 ~23 minecraft:chiseled_quartz_block
setblock ~62 ~15 ~22 minecraft:quartz_stairs[facing=south,half=bottom]
setblock ~62 ~17 ~22 minecraft:quartz_stairs[facing=south,half=top]
fill ~62 ~18 ~23 ~62 ~20 ~24 minecraft:smooth_quartz
setblock ~62 ~19 ~23 minecraft:chiseled_quartz_block
setblock ~62 ~21 ~23 minecraft:smooth_quartz
setblock ~62 ~21 ~24 minecraft:smooth_quartz
setblock ~62 ~21 ~22 minecraft:quartz_stairs[facing=south,half=top]
fill ~62 ~30 ~23 ~62 ~32 ~24 minecraft:smooth_quartz
setblock ~62 ~31 ~23 minecraft:chiseled_quartz_block
setblock ~62 ~33 ~23 minecraft:smooth_quartz
setblock ~62 ~33 ~24 minecraft:smooth_quartz
setblock ~62 ~33 ~22 minecraft:quartz_stairs[facing=south,half=top]
setblock ~62 ~34 ~23 minecraft:quartz_slab[type=bottom]
setblock ~62 ~6 ~23 minecraft:diorite_wall
setblock ~62 ~7 ~23 minecraft:quartz_slab[type=bottom]
fill ~61 ~0 ~22 ~61 ~4 ~23 minecraft:smooth_quartz
fill ~61 ~2 ~22 ~61 ~3 ~22 minecraft:chiseled_quartz_block
setblock ~61 ~5 ~22 minecraft:smooth_quartz
setblock ~61 ~5 ~23 minecraft:smooth_quartz
setblock ~61 ~5 ~21 minecraft:quartz_stairs[facing=south,half=top]
fill ~61 ~15 ~22 ~61 ~17 ~23 minecraft:smooth_quartz
setblock ~61 ~16 ~22 minecraft:chiseled_quartz_block
setblock ~61 ~15 ~21 minecraft:quartz_stairs[facing=south,half=bottom]
setblock ~61 ~17 ~21 minecraft:quartz_stairs[facing=south,half=top]
fill ~61 ~18 ~22 ~61 ~20 ~23 minecraft:smooth_quartz
setblock ~61 ~19 ~22 minecraft:chiseled_quartz_block
setblock ~61 ~21 ~22 minecraft:smooth_quartz
setblock ~61 ~21 ~23 minecraft:smooth_quartz
setblock ~61 ~21 ~21 minecraft:quartz_stairs[facing=south,half=top]
fill ~61 ~30 ~22 ~61 ~32 ~23 minecraft:smooth_quartz
setblock ~61 ~31 ~22 minecraft:chiseled_quartz_block
setblock ~61 ~33 ~22 minecraft:smooth_quartz
setblock ~61 ~33 ~23 minecraft:smooth_quartz
setblock ~61 ~33 ~21 minecraft:quartz_stairs[facing=south,half=top]
setblock ~61 ~34 ~22 minecraft:quartz_slab[type=bottom]
setblock ~61 ~6 ~22 minecraft:diorite_wall
setblock ~61 ~7 ~22 minecraft:quartz_slab[type=bottom]
fill ~60 ~0 ~21 ~60 ~4 ~22 minecraft:smooth_quartz
fill ~60 ~2 ~21 ~60 ~3 ~21 minecraft:chiseled_quartz_block
setblock ~60 ~5 ~21 minecraft:smooth_quartz
setblock ~60 ~5 ~22 minecraft:smooth_quartz
setblock ~60 ~5 ~20 minecraft:quartz_stairs[facing=south,half=top]
fill ~60 ~15 ~21 ~60 ~17 ~22 minecraft:smooth_quartz
setblock ~60 ~16 ~21 minecraft:chiseled_quartz_block
setblock ~60 ~15 ~20 minecraft:quartz_stairs[facing=south,half=bottom]
setblock ~60 ~17 ~20 minecraft:quartz_stairs[facing=south,half=top]
fill ~60 ~18 ~21 ~60 ~20 ~22 minecraft:smooth_quartz
setblock ~60 ~19 ~21 minecraft:chiseled_quartz_block
setblock ~60 ~21 ~21 minecraft:smooth_quartz
setblock ~60 ~21 ~22 minecraft:smooth_quartz
setblock ~60 ~21 ~20 minecraft:quartz_stairs[facing=south,half=top]
fill ~60 ~30 ~21 ~60 ~32 ~22 minecraft:smooth_quartz
setblock ~60 ~31 ~21 minecraft:chiseled_quartz_block
setblock ~60 ~33 ~21 minecraft:smooth_quartz
setblock ~60 ~33 ~22 minecraft:smooth_quartz
setblock ~60 ~33 ~20 minecraft:quartz_stairs[facing=south,half=top]
setblock ~60 ~34 ~21 minecraft:quartz_slab[type=bottom]
setblock ~60 ~6 ~21 minecraft:diorite_wall
setblock ~60 ~7 ~21 minecraft:quartz_slab[type=bottom]
fill ~59 ~0 ~20 ~59 ~4 ~21 minecraft:smooth_quartz
fill ~59 ~2 ~20 ~59 ~3 ~20 minecraft:chiseled_quartz_block
setblock ~59 ~5 ~20 minecraft:smooth_quartz
setblock ~59 ~5 ~21 minecraft:smooth_quartz
setblock ~59 ~5 ~19 minecraft:quartz_stairs[facing=south,half=top]
fill ~59 ~15 ~20 ~59 ~17 ~21 minecraft:smooth_quartz
setblock ~59 ~16 ~20 minecraft:chiseled_quartz_block
setblock ~59 ~15 ~19 minecraft:quartz_stairs[facing=south,half=bottom]
setblock ~59 ~17 ~19 minecraft:quartz_stairs[facing=south,half=top]
fill ~59 ~18 ~20 ~59 ~20 ~21 minecraft:smooth_quartz
setblock ~59 ~19 ~20 minecraft:chiseled_quartz_block
setblock ~59 ~21 ~20 minecraft:smooth_quartz
setblock ~59 ~21 ~21 minecraft:smooth_quartz
setblock ~59 ~21 ~19 minecraft:quartz_stairs[facing=south,half=top]
fill ~59 ~30 ~20 ~59 ~32 ~21 minecraft:smooth_quartz
setblock ~59 ~31 ~20 minecraft:chiseled_quartz_block
setblock ~59 ~33 ~20 minecraft:smooth_quartz
setblock ~59 ~33 ~21 minecraft:smooth_quartz
setblock ~59 ~33 ~19 minecraft:quartz_stairs[facing=south,half=top]
setblock ~59 ~34 ~20 minecraft:quartz_slab[type=bottom]
setblock ~59 ~6 ~20 minecraft:diorite_wall
setblock ~59 ~7 ~20 minecraft:quartz_slab[type=bottom]
fill ~58 ~0 ~19 ~58 ~4 ~20 minecraft:smooth_quartz
fill ~58 ~2 ~19 ~58 ~3 ~19 minecraft:chiseled_quartz_block
setblock ~58 ~5 ~19 minecraft:smooth_quartz
setblock ~58 ~5 ~20 minecraft:smooth_quartz
setblock ~58 ~5 ~18 minecraft:quartz_stairs[facing=south,half=top]
fill ~58 ~15 ~19 ~58 ~17 ~20 minecraft:smooth_quartz
setblock ~58 ~16 ~19 minecraft:chiseled_quartz_block
setblock ~58 ~15 ~18 minecraft:quartz_stairs[facing=south,half=bottom]
setblock ~58 ~17 ~18 minecraft:quartz_stairs[facing=south,half=top]
fill ~58 ~18 ~19 ~58 ~20 ~20 minecraft:smooth_quartz
setblock ~58 ~19 ~19 minecraft:chiseled_quartz_block
setblock ~58 ~21 ~19 minecraft:smooth_quartz
setblock ~58 ~21 ~20 minecraft:smooth_quartz
setblock ~58 ~21 ~18 minecraft:quartz_stairs[facing=south,half=top]
fill ~58 ~30 ~19 ~58 ~32 ~20 minecraft:smooth_quartz
setblock ~58 ~31 ~19 minecraft:chiseled_quartz_block
setblock ~58 ~33 ~19 minecraft:smooth_quartz
setblock ~58 ~33 ~20 minecraft:smooth_quartz
setblock ~58 ~33 ~18 minecraft:quartz_stairs[facing=south,half=top]
setblock ~58 ~34 ~19 minecraft:quartz_slab[type=bottom]
setblock ~58 ~6 ~19 minecraft:diorite_wall
setblock ~58 ~7 ~19 minecraft:quartz_slab[type=bottom]
fill ~57 ~0 ~18 ~57 ~4 ~19 minecraft:smooth_quartz
fill ~57 ~2 ~18 ~57 ~3 ~18 minecraft:chiseled_quartz_block
setblock ~57 ~5 ~18 minecraft:smooth_quartz
setblock ~57 ~5 ~19 minecraft:smooth_quartz
setblock ~57 ~5 ~17 minecraft:quartz_stairs[facing=south,half=top]
fill ~57 ~15 ~18 ~57 ~17 ~19 minecraft:smooth_quartz
setblock ~57 ~16 ~18 minecraft:chiseled_quartz_block
setblock ~57 ~15 ~17 minecraft:quartz_stairs[facing=south,half=bottom]
setblock ~57 ~17 ~17 minecraft:quartz_stairs[facing=south,half=top]
fill ~57 ~18 ~18 ~57 ~20 ~19 minecraft:smooth_quartz
setblock ~57 ~19 ~18 minecraft:chiseled_quartz_block
setblock ~57 ~21 ~18 minecraft:smooth_quartz
setblock ~57 ~21 ~19 minecraft:smooth_quartz
setblock ~57 ~21 ~17 minecraft:quartz_stairs[facing=south,half=top]
fill ~57 ~30 ~18 ~57 ~32 ~19 minecraft:smooth_quartz
setblock ~57 ~31 ~18 minecraft:chiseled_quartz_block
setblock ~57 ~33 ~18 minecraft:smooth_quartz
setblock ~57 ~33 ~19 minecraft:smooth_quartz
setblock ~57 ~33 ~17 minecraft:quartz_stairs[facing=south,half=top]
setblock ~57 ~34 ~18 minecraft:quartz_slab[type=bottom]
setblock ~57 ~6 ~18 minecraft:diorite_wall
setblock ~57 ~7 ~18 minecraft:quartz_slab[type=bottom]
fill ~56 ~0 ~18 ~56 ~4 ~19 minecraft:smooth_quartz
fill ~56 ~2 ~18 ~56 ~3 ~18 minecraft:chiseled_quartz_block
setblock ~56 ~5 ~18 minecraft:smooth_quartz
setblock ~56 ~5 ~19 minecraft:smooth_quartz
setblock ~56 ~5 ~17 minecraft:quartz_stairs[facing=south,half=top]
fill ~56 ~15 ~18 ~56 ~17 ~19 minecraft:smooth_quartz
setblock ~56 ~16 ~18 minecraft:chiseled_quartz_block
setblock ~56 ~15 ~17 minecraft:quartz_stairs[facing=south,half=bottom]
setblock ~56 ~17 ~17 minecraft:quartz_stairs[facing=south,half=top]
fill ~56 ~18 ~18 ~56 ~20 ~19 minecraft:smooth_quartz
setblock ~56 ~19 ~18 minecraft:chiseled_quartz_block
setblock ~56 ~21 ~18 minecraft:smooth_quartz
setblock ~56 ~21 ~19 minecraft:smooth_quartz
setblock ~56 ~21 ~17 minecraft:quartz_stairs[facing=south,half=top]
fill ~56 ~30 ~18 ~56 ~32 ~19 minecraft:smooth_quartz
setblock ~56 ~31 ~18 minecraft:chiseled_quartz_block
setblock ~56 ~33 ~18 minecraft:smooth_quartz
setblock ~56 ~33 ~19 minecraft:smooth_quartz
setblock ~56 ~33 ~17 minecraft:quartz_stairs[facing=south,half=top]
setblock ~56 ~34 ~18 minecraft:quartz_slab[type=bottom]
setblock ~56 ~6 ~18 minecraft:diorite_wall
setblock ~56 ~7 ~18 minecraft:quartz_slab[type=bottom]
fill ~55 ~0 ~17 ~55 ~4 ~18 minecraft:smooth_quartz
fill ~55 ~2 ~17 ~55 ~3 ~17 minecraft:chiseled_quartz_block
setblock ~55 ~5 ~17 minecraft:smooth_quartz
setblock ~55 ~5 ~18 minecraft:smooth_quartz
setblock ~55 ~5 ~16 minecraft:quartz_stairs[facing=south,half=top]
fill ~55 ~15 ~17 ~55 ~17 ~18 minecraft:smooth_quartz
setblock ~55 ~16 ~17 minecraft:chiseled_quartz_block
setblock ~55 ~15 ~16 minecraft:quartz_stairs[facing=south,half=bottom]
setblock ~55 ~17 ~16 minecraft:quartz_stairs[facing=south,half=top]
fill ~55 ~18 ~17 ~55 ~20 ~18 minecraft:smooth_quartz
setblock ~55 ~19 ~17 minecraft:chiseled_quartz_block
setblock ~55 ~21 ~17 minecraft:smooth_quartz
setblock ~55 ~21 ~18 minecraft:smooth_quartz
setblock ~55 ~21 ~16 minecraft:quartz_stairs[facing=south,half=top]
fill ~55 ~30 ~17 ~55 ~32 ~18 minecraft:smooth_quartz
setblock ~55 ~31 ~17 minecraft:chiseled_quartz_block
setblock ~55 ~33 ~17 minecraft:smooth_quartz
setblock ~55 ~33 ~18 minecraft:smooth_quartz
setblock ~55 ~33 ~16 minecraft:quartz_stairs[facing=south,half=top]
setblock ~55 ~34 ~17 minecraft:quartz_slab[type=bottom]
fill ~54 ~0 ~17 ~54 ~4 ~18 minecraft:smooth_quartz
fill ~54 ~2 ~17 ~54 ~3 ~17 minecraft:chiseled_quartz_block
setblock ~54 ~5 ~17 minecraft:smooth_quartz
setblock ~54 ~5 ~18 minecraft:smooth_quartz
setblock ~54 ~5 ~16 minecraft:quartz_stairs[facing=south,half=top]
fill ~54 ~15 ~17 ~54 ~17 ~18 minecraft:smooth_quartz
setblock ~54 ~16 ~17 minecraft:chiseled_quartz_block
setblock ~54 ~15 ~16 minecraft:quartz_stairs[facing=south,half=bottom]
setblock ~54 ~17 ~16 minecraft:quartz_stairs[facing=south,half=top]
fill ~54 ~18 ~17 ~54 ~20 ~18 minecraft:smooth_quartz
setblock ~54 ~19 ~17 minecraft:chiseled_quartz_block
setblock ~54 ~21 ~17 minecraft:smooth_quartz
setblock ~54 ~21 ~18 minecraft:smooth_quartz
setblock ~54 ~21 ~16 minecraft:quartz_stairs[facing=south,half=top]
fill ~54 ~30 ~17 ~54 ~32 ~18 minecraft:smooth_quartz
setblock ~54 ~31 ~17 minecraft:chiseled_quartz_block
setblock ~54 ~33 ~17 minecraft:smooth_quartz
setblock ~54 ~33 ~18 minecraft:smooth_quartz
setblock ~54 ~33 ~16 minecraft:quartz_stairs[facing=south,half=top]
setblock ~54 ~34 ~17 minecraft:quartz_slab[type=bottom]
fill ~53 ~0 ~16 ~53 ~4 ~17 minecraft:smooth_quartz
fill ~53 ~2 ~16 ~53 ~3 ~16 minecraft:chiseled_quartz_block
setblock ~53 ~5 ~16 minecraft:smooth_quartz
setblock ~53 ~5 ~17 minecraft:smooth_quartz
setblock ~53 ~5 ~15 minecraft:quartz_stairs[facing=south,half=top]
fill ~53 ~15 ~16 ~53 ~17 ~17 minecraft:smooth_quartz
setblock ~53 ~16 ~16 minecraft:chiseled_quartz_block
setblock ~53 ~15 ~15 minecraft:quartz_stairs[facing=south,half=bottom]
setblock ~53 ~17 ~15 minecraft:quartz_stairs[facing=south,half=top]
fill ~53 ~18 ~16 ~53 ~20 ~17 minecraft:smooth_quartz
setblock ~53 ~19 ~16 minecraft:chiseled_quartz_block
setblock ~53 ~21 ~16 minecraft:smooth_quartz
setblock ~53 ~21 ~17 minecraft:smooth_quartz
setblock ~53 ~21 ~15 minecraft:quartz_stairs[facing=south,half=top]
fill ~53 ~30 ~16 ~53 ~32 ~17 minecraft:smooth_quartz
setblock ~53 ~31 ~16 minecraft:chiseled_quartz_block
setblock ~53 ~33 ~16 minecraft:smooth_quartz
setblock ~53 ~33 ~17 minecraft:smooth_quartz
setblock ~53 ~33 ~15 minecraft:quartz_stairs[facing=south,half=top]
setblock ~53 ~34 ~16 minecraft:quartz_slab[type=bottom]
setblock ~53 ~6 ~16 minecraft:diorite_wall
setblock ~53 ~7 ~16 minecraft:quartz_slab[type=bottom]
fill ~52 ~0 ~16 ~52 ~4 ~17 minecraft:smooth_quartz
fill ~52 ~2 ~16 ~52 ~3 ~16 minecraft:chiseled_quartz_block
setblock ~52 ~5 ~16 minecraft:smooth_quartz
setblock ~52 ~5 ~17 minecraft:smooth_quartz
setblock ~52 ~5 ~15 minecraft:quartz_stairs[facing=south,half=top]
fill ~52 ~15 ~16 ~52 ~17 ~17 minecraft:smooth_quartz
setblock ~52 ~16 ~16 minecraft:chiseled_quartz_block
setblock ~52 ~15 ~15 minecraft:quartz_stairs[facing=south,half=bottom]
setblock ~52 ~17 ~15 minecraft:quartz_stairs[facing=south,half=top]
fill ~52 ~18 ~16 ~52 ~20 ~17 minecraft:smooth_quartz
setblock ~52 ~19 ~16 minecraft:chiseled_quartz_block
setblock ~52 ~21 ~16 minecraft:smooth_quartz
setblock ~52 ~21 ~17 minecraft:smooth_quartz
setblock ~52 ~21 ~15 minecraft:quartz_stairs[facing=south,half=top]
fill ~52 ~30 ~16 ~52 ~32 ~17 minecraft:smooth_quartz
setblock ~52 ~31 ~16 minecraft:chiseled_quartz_block
setblock ~52 ~33 ~16 minecraft:smooth_quartz
setblock ~52 ~33 ~17 minecraft:smooth_quartz
setblock ~52 ~33 ~15 minecraft:quartz_stairs[facing=south,half=top]
setblock ~52 ~34 ~16 minecraft:quartz_slab[type=bottom]
setblock ~52 ~6 ~16 minecraft:diorite_wall
setblock ~52 ~7 ~16 minecraft:quartz_slab[type=bottom]
fill ~51 ~0 ~16 ~51 ~4 ~17 minecraft:smooth_quartz
fill ~51 ~2 ~16 ~51 ~3 ~16 minecraft:chiseled_quartz_block
setblock ~51 ~5 ~16 minecraft:smooth_quartz
setblock ~51 ~5 ~17 minecraft:smooth_quartz
setblock ~51 ~5 ~15 minecraft:quartz_stairs[facing=south,half=top]
fill ~51 ~15 ~16 ~51 ~17 ~17 minecraft:smooth_quartz
setblock ~51 ~16 ~16 minecraft:chiseled_quartz_block
setblock ~51 ~15 ~15 minecraft:quartz_stairs[facing=south,half=bottom]
setblock ~51 ~17 ~15 minecraft:quartz_stairs[facing=south,half=top]
fill ~51 ~18 ~16 ~51 ~20 ~17 minecraft:smooth_quartz
setblock ~51 ~19 ~16 minecraft:chiseled_quartz_block
setblock ~51 ~21 ~16 minecraft:smooth_quartz
setblock ~51 ~21 ~17 minecraft:smooth_quartz
setblock ~51 ~21 ~15 minecraft:quartz_stairs[facing=south,half=top]
fill ~51 ~30 ~16 ~51 ~32 ~17 minecraft:smooth_quartz
setblock ~51 ~31 ~16 minecraft:chiseled_quartz_block
setblock ~51 ~33 ~16 minecraft:smooth_quartz
setblock ~51 ~33 ~17 minecraft:smooth_quartz
setblock ~51 ~33 ~15 minecraft:quartz_stairs[facing=south,half=top]
setblock ~51 ~34 ~16 minecraft:quartz_slab[type=bottom]
setblock ~51 ~6 ~16 minecraft:diorite_wall
setblock ~51 ~7 ~16 minecraft:quartz_slab[type=bottom]
fill ~50 ~0 ~15 ~50 ~4 ~16 minecraft:smooth_quartz
fill ~50 ~2 ~15 ~50 ~3 ~15 minecraft:chiseled_quartz_block
setblock ~50 ~5 ~15 minecraft:smooth_quartz
setblock ~50 ~5 ~16 minecraft:smooth_quartz
setblock ~50 ~5 ~14 minecraft:quartz_stairs[facing=south,half=top]
fill ~50 ~15 ~15 ~50 ~17 ~16 minecraft:smooth_quartz
setblock ~50 ~16 ~15 minecraft:chiseled_quartz_block
setblock ~50 ~15 ~14 minecraft:quartz_stairs[facing=south,half=bottom]
setblock ~50 ~17 ~14 minecraft:quartz_stairs[facing=south,half=top]
fill ~50 ~18 ~15 ~50 ~20 ~16 minecraft:smooth_quartz
setblock ~50 ~19 ~15 minecraft:chiseled_quartz_block
setblock ~50 ~21 ~15 minecraft:smooth_quartz
setblock ~50 ~21 ~16 minecraft:smooth_quartz
setblock ~50 ~21 ~14 minecraft:quartz_stairs[facing=south,half=top]
fill ~50 ~30 ~15 ~50 ~32 ~16 minecraft:smooth_quartz
setblock ~50 ~31 ~15 minecraft:chiseled_quartz_block
setblock ~50 ~33 ~15 minecraft:smooth_quartz
setblock ~50 ~33 ~16 minecraft:smooth_quartz
setblock ~50 ~33 ~14 minecraft:quartz_stairs[facing=south,half=top]
setblock ~50 ~34 ~15 minecraft:quartz_slab[type=bottom]
setblock ~50 ~6 ~15 minecraft:diorite_wall
setblock ~50 ~7 ~15 minecraft:quartz_slab[type=bottom]
fill ~49 ~0 ~15 ~49 ~4 ~16 minecraft:smooth_quartz
fill ~49 ~2 ~15 ~49 ~3 ~15 minecraft:chiseled_quartz_block
setblock ~49 ~5 ~15 minecraft:smooth_quartz
setblock ~49 ~5 ~16 minecraft:smooth_quartz
setblock ~49 ~5 ~14 minecraft:quartz_stairs[facing=south,half=top]
fill ~49 ~15 ~15 ~49 ~17 ~16 minecraft:smooth_quartz
setblock ~49 ~16 ~15 minecraft:chiseled_quartz_block
setblock ~49 ~15 ~14 minecraft:quartz_stairs[facing=south,half=bottom]
setblock ~49 ~17 ~14 minecraft:quartz_stairs[facing=south,half=top]
fill ~49 ~18 ~15 ~49 ~20 ~16 minecraft:smooth_quartz
setblock ~49 ~19 ~15 minecraft:chiseled_quartz_block
setblock ~49 ~21 ~15 minecraft:smooth_quartz
setblock ~49 ~21 ~16 minecraft:smooth_quartz
setblock ~49 ~21 ~14 minecraft:quartz_stairs[facing=south,half=top]
fill ~49 ~30 ~15 ~49 ~32 ~16 minecraft:smooth_quartz
setblock ~49 ~31 ~15 minecraft:chiseled_quartz_block
setblock ~49 ~33 ~15 minecraft:smooth_quartz
setblock ~49 ~33 ~16 minecraft:smooth_quartz
setblock ~49 ~33 ~14 minecraft:quartz_stairs[facing=south,half=top]
setblock ~49 ~34 ~15 minecraft:quartz_slab[type=bottom]
setblock ~49 ~6 ~15 minecraft:diorite_wall
setblock ~49 ~7 ~15 minecraft:quartz_slab[type=bottom]
fill ~48 ~0 ~15 ~48 ~4 ~16 minecraft:smooth_quartz
fill ~48 ~2 ~15 ~48 ~3 ~15 minecraft:chiseled_quartz_block
setblock ~48 ~5 ~15 minecraft:smooth_quartz
setblock ~48 ~5 ~16 minecraft:smooth_quartz
setblock ~48 ~5 ~14 minecraft:quartz_stairs[facing=south,half=top]
fill ~48 ~15 ~15 ~48 ~17 ~16 minecraft:smooth_quartz
setblock ~48 ~16 ~15 minecraft:chiseled_quartz_block
setblock ~48 ~15 ~14 minecraft:quartz_stairs[facing=south,half=bottom]
setblock ~48 ~17 ~14 minecraft:quartz_stairs[facing=south,half=top]
fill ~48 ~18 ~15 ~48 ~20 ~16 minecraft:smooth_quartz
setblock ~48 ~19 ~15 minecraft:chiseled_quartz_block
setblock ~48 ~21 ~15 minecraft:smooth_quartz
setblock ~48 ~21 ~16 minecraft:smooth_quartz
setblock ~48 ~21 ~14 minecraft:quartz_stairs[facing=south,half=top]
fill ~48 ~30 ~15 ~48 ~32 ~16 minecraft:smooth_quartz
setblock ~48 ~31 ~15 minecraft:chiseled_quartz_block
setblock ~48 ~33 ~15 minecraft:smooth_quartz
setblock ~48 ~33 ~16 minecraft:smooth_quartz
setblock ~48 ~33 ~14 minecraft:quartz_stairs[facing=south,half=top]
setblock ~48 ~34 ~15 minecraft:quartz_slab[type=bottom]
setblock ~48 ~6 ~15 minecraft:diorite_wall
setblock ~48 ~7 ~15 minecraft:quartz_slab[type=bottom]
fill ~47 ~0 ~15 ~47 ~4 ~16 minecraft:smooth_quartz
fill ~47 ~2 ~15 ~47 ~3 ~15 minecraft:chiseled_quartz_block
setblock ~47 ~5 ~15 minecraft:smooth_quartz
setblock ~47 ~5 ~16 minecraft:smooth_quartz
setblock ~47 ~5 ~14 minecraft:quartz_stairs[facing=south,half=top]
fill ~47 ~15 ~15 ~47 ~17 ~16 minecraft:smooth_quartz
setblock ~47 ~16 ~15 minecraft:chiseled_quartz_block
setblock ~47 ~15 ~14 minecraft:quartz_stairs[facing=south,half=bottom]
setblock ~47 ~17 ~14 minecraft:quartz_stairs[facing=south,half=top]
fill ~47 ~18 ~15 ~47 ~20 ~16 minecraft:smooth_quartz
setblock ~47 ~19 ~15 minecraft:chiseled_quartz_block
setblock ~47 ~21 ~15 minecraft:smooth_quartz
setblock ~47 ~21 ~16 minecraft:smooth_quartz
setblock ~47 ~21 ~14 minecraft:quartz_stairs[facing=south,half=top]
fill ~47 ~30 ~15 ~47 ~32 ~16 minecraft:smooth_quartz
setblock ~47 ~31 ~15 minecraft:chiseled_quartz_block
setblock ~47 ~33 ~15 minecraft:smooth_quartz
setblock ~47 ~33 ~16 minecraft:smooth_quartz
setblock ~47 ~33 ~14 minecraft:quartz_stairs[facing=south,half=top]
setblock ~47 ~34 ~15 minecraft:quartz_slab[type=bottom]
setblock ~47 ~6 ~15 minecraft:diorite_wall
setblock ~47 ~7 ~15 minecraft:quartz_slab[type=bottom]
fill ~46 ~0 ~15 ~46 ~4 ~16 minecraft:smooth_quartz
fill ~46 ~2 ~15 ~46 ~3 ~15 minecraft:chiseled_quartz_block
setblock ~46 ~5 ~15 minecraft:smooth_quartz
setblock ~46 ~5 ~16 minecraft:smooth_quartz
setblock ~46 ~5 ~14 minecraft:quartz_stairs[facing=south,half=top]
fill ~46 ~15 ~15 ~46 ~17 ~16 minecraft:smooth_quartz
setblock ~46 ~16 ~15 minecraft:chiseled_quartz_block
setblock ~46 ~15 ~14 minecraft:quartz_stairs[facing=south,half=bottom]
setblock ~46 ~17 ~14 minecraft:quartz_stairs[facing=south,half=top]
fill ~46 ~18 ~15 ~46 ~20 ~16 minecraft:smooth_quartz
setblock ~46 ~19 ~15 minecraft:chiseled_quartz_block
setblock ~46 ~21 ~15 minecraft:smooth_quartz
setblock ~46 ~21 ~16 minecraft:smooth_quartz
setblock ~46 ~21 ~14 minecraft:quartz_stairs[facing=south,half=top]
fill ~46 ~30 ~15 ~46 ~32 ~16 minecraft:smooth_quartz
setblock ~46 ~31 ~15 minecraft:chiseled_quartz_block
setblock ~46 ~33 ~15 minecraft:smooth_quartz
setblock ~46 ~33 ~16 minecraft:smooth_quartz
setblock ~46 ~33 ~14 minecraft:quartz_stairs[facing=south,half=top]
setblock ~46 ~34 ~15 minecraft:quartz_slab[type=bottom]
fill ~45 ~0 ~15 ~45 ~4 ~16 minecraft:smooth_quartz
fill ~45 ~2 ~15 ~45 ~3 ~15 minecraft:chiseled_quartz_block
setblock ~45 ~5 ~15 minecraft:smooth_quartz
setblock ~45 ~5 ~16 minecraft:smooth_quartz
setblock ~45 ~5 ~14 minecraft:quartz_stairs[facing=south,half=top]
fill ~45 ~15 ~15 ~45 ~17 ~16 minecraft:smooth_quartz
setblock ~45 ~16 ~15 minecraft:chiseled_quartz_block
setblock ~45 ~15 ~14 minecraft:quartz_stairs[facing=south,half=bottom]
setblock ~45 ~17 ~14 minecraft:quartz_stairs[facing=south,half=top]
fill ~45 ~18 ~15 ~45 ~20 ~16 minecraft:smooth_quartz
setblock ~45 ~19 ~15 minecraft:chiseled_quartz_block
setblock ~45 ~21 ~15 minecraft:smooth_quartz
setblock ~45 ~21 ~16 minecraft:smooth_quartz
setblock ~45 ~21 ~14 minecraft:quartz_stairs[facing=south,half=top]
fill ~45 ~30 ~15 ~45 ~32 ~16 minecraft:smooth_quartz
setblock ~45 ~31 ~15 minecraft:chiseled_quartz_block
setblock ~45 ~33 ~15 minecraft:smooth_quartz
setblock ~45 ~33 ~16 minecraft:smooth_quartz
setblock ~45 ~33 ~14 minecraft:quartz_stairs[facing=south,half=top]
setblock ~45 ~34 ~15 minecraft:quartz_slab[type=bottom]
fill ~44 ~0 ~15 ~44 ~4 ~16 minecraft:smooth_quartz
fill ~44 ~2 ~15 ~44 ~3 ~15 minecraft:chiseled_quartz_block
setblock ~44 ~5 ~15 minecraft:smooth_quartz
setblock ~44 ~5 ~16 minecraft:smooth_quartz
setblock ~44 ~5 ~14 minecraft:quartz_stairs[facing=south,half=top]
fill ~44 ~15 ~15 ~44 ~17 ~16 minecraft:smooth_quartz
setblock ~44 ~16 ~15 minecraft:chiseled_quartz_block
setblock ~44 ~15 ~14 minecraft:quartz_stairs[facing=south,half=bottom]
setblock ~44 ~17 ~14 minecraft:quartz_stairs[facing=south,half=top]
fill ~44 ~18 ~15 ~44 ~20 ~16 minecraft:smooth_quartz
setblock ~44 ~19 ~15 minecraft:chiseled_quartz_block
setblock ~44 ~21 ~15 minecraft:smooth_quartz
setblock ~44 ~21 ~16 minecraft:smooth_quartz
setblock ~44 ~21 ~14 minecraft:quartz_stairs[facing=south,half=top]
fill ~44 ~30 ~15 ~44 ~32 ~16 minecraft:smooth_quartz
setblock ~44 ~31 ~15 minecraft:chiseled_quartz_block
setblock ~44 ~33 ~15 minecraft:smooth_quartz
setblock ~44 ~33 ~16 minecraft:smooth_quartz
setblock ~44 ~33 ~14 minecraft:quartz_stairs[facing=south,half=top]
setblock ~44 ~34 ~15 minecraft:quartz_slab[type=bottom]
setblock ~44 ~6 ~15 minecraft:diorite_wall
setblock ~44 ~7 ~15 minecraft:quartz_slab[type=bottom]
fill ~43 ~0 ~15 ~43 ~4 ~16 minecraft:smooth_quartz
fill ~43 ~2 ~15 ~43 ~3 ~15 minecraft:chiseled_quartz_block
setblock ~43 ~5 ~15 minecraft:smooth_quartz
setblock ~43 ~5 ~16 minecraft:smooth_quartz
setblock ~43 ~5 ~14 minecraft:quartz_stairs[facing=south,half=top]
fill ~43 ~15 ~15 ~43 ~17 ~16 minecraft:smooth_quartz
setblock ~43 ~16 ~15 minecraft:chiseled_quartz_block
setblock ~43 ~15 ~14 minecraft:quartz_stairs[facing=south,half=bottom]
setblock ~43 ~17 ~14 minecraft:quartz_stairs[facing=south,half=top]
fill ~43 ~18 ~15 ~43 ~20 ~16 minecraft:smooth_quartz
setblock ~43 ~19 ~15 minecraft:chiseled_quartz_block
setblock ~43 ~21 ~15 minecraft:smooth_quartz
setblock ~43 ~21 ~16 minecraft:smooth_quartz
setblock ~43 ~21 ~14 minecraft:quartz_stairs[facing=south,half=top]
fill ~43 ~30 ~15 ~43 ~32 ~16 minecraft:smooth_quartz
setblock ~43 ~31 ~15 minecraft:chiseled_quartz_block
setblock ~43 ~33 ~15 minecraft:smooth_quartz
setblock ~43 ~33 ~16 minecraft:smooth_quartz
setblock ~43 ~33 ~14 minecraft:quartz_stairs[facing=south,half=top]
setblock ~43 ~34 ~15 minecraft:quartz_slab[type=bottom]
setblock ~43 ~6 ~15 minecraft:diorite_wall
setblock ~43 ~7 ~15 minecraft:quartz_slab[type=bottom]
fill ~42 ~0 ~15 ~42 ~4 ~16 minecraft:smooth_quartz
fill ~42 ~2 ~15 ~42 ~3 ~15 minecraft:chiseled_quartz_block
setblock ~42 ~5 ~15 minecraft:smooth_quartz
setblock ~42 ~5 ~16 minecraft:smooth_quartz
setblock ~42 ~5 ~14 minecraft:quartz_stairs[facing=south,half=top]
fill ~42 ~15 ~15 ~42 ~17 ~16 minecraft:smooth_quartz
setblock ~42 ~16 ~15 minecraft:chiseled_quartz_block
setblock ~42 ~15 ~14 minecraft:quartz_stairs[facing=south,half=bottom]
setblock ~42 ~17 ~14 minecraft:quartz_stairs[facing=south,half=top]
fill ~42 ~18 ~15 ~42 ~20 ~16 minecraft:smooth_quartz
setblock ~42 ~19 ~15 minecraft:chiseled_quartz_block
setblock ~42 ~21 ~15 minecraft:smooth_quartz
setblock ~42 ~21 ~16 minecraft:smooth_quartz
setblock ~42 ~21 ~14 minecraft:quartz_stairs[facing=south,half=top]
fill ~42 ~30 ~15 ~42 ~32 ~16 minecraft:smooth_quartz
setblock ~42 ~31 ~15 minecraft:chiseled_quartz_block
setblock ~42 ~33 ~15 minecraft:smooth_quartz
setblock ~42 ~33 ~16 minecraft:smooth_quartz
setblock ~42 ~33 ~14 minecraft:quartz_stairs[facing=south,half=top]
setblock ~42 ~34 ~15 minecraft:quartz_slab[type=bottom]
setblock ~42 ~6 ~15 minecraft:diorite_wall
setblock ~42 ~7 ~15 minecraft:quartz_slab[type=bottom]
fill ~41 ~0 ~15 ~41 ~4 ~16 minecraft:smooth_quartz
fill ~41 ~2 ~15 ~41 ~3 ~15 minecraft:chiseled_quartz_block
setblock ~41 ~5 ~15 minecraft:smooth_quartz
setblock ~41 ~5 ~16 minecraft:smooth_quartz
setblock ~41 ~5 ~14 minecraft:quartz_stairs[facing=south,half=top]
fill ~41 ~15 ~15 ~41 ~17 ~16 minecraft:smooth_quartz
setblock ~41 ~16 ~15 minecraft:chiseled_quartz_block
setblock ~41 ~15 ~14 minecraft:quartz_stairs[facing=south,half=bottom]
setblock ~41 ~17 ~14 minecraft:quartz_stairs[facing=south,half=top]
fill ~41 ~18 ~15 ~41 ~20 ~16 minecraft:smooth_quartz
setblock ~41 ~19 ~15 minecraft:chiseled_quartz_block
setblock ~41 ~21 ~15 minecraft:smooth_quartz
setblock ~41 ~21 ~16 minecraft:smooth_quartz
setblock ~41 ~21 ~14 minecraft:quartz_stairs[facing=south,half=top]
fill ~41 ~30 ~15 ~41 ~32 ~16 minecraft:smooth_quartz
setblock ~41 ~31 ~15 minecraft:chiseled_quartz_block
setblock ~41 ~33 ~15 minecraft:smooth_quartz
setblock ~41 ~33 ~16 minecraft:smooth_quartz
setblock ~41 ~33 ~14 minecraft:quartz_stairs[facing=south,half=top]
setblock ~41 ~34 ~15 minecraft:quartz_slab[type=bottom]
setblock ~41 ~6 ~15 minecraft:diorite_wall
setblock ~41 ~7 ~15 minecraft:quartz_slab[type=bottom]
fill ~40 ~0 ~16 ~40 ~4 ~17 minecraft:smooth_quartz
fill ~40 ~2 ~16 ~40 ~3 ~16 minecraft:chiseled_quartz_block
setblock ~40 ~5 ~16 minecraft:smooth_quartz
setblock ~40 ~5 ~17 minecraft:smooth_quartz
setblock ~40 ~5 ~15 minecraft:quartz_stairs[facing=south,half=top]
fill ~40 ~15 ~16 ~40 ~17 ~17 minecraft:smooth_quartz
setblock ~40 ~16 ~16 minecraft:chiseled_quartz_block
setblock ~40 ~15 ~15 minecraft:quartz_stairs[facing=south,half=bottom]
setblock ~40 ~17 ~15 minecraft:quartz_stairs[facing=south,half=top]
fill ~40 ~18 ~16 ~40 ~20 ~17 minecraft:smooth_quartz
setblock ~40 ~19 ~16 minecraft:chiseled_quartz_block
setblock ~40 ~21 ~16 minecraft:smooth_quartz
setblock ~40 ~21 ~17 minecraft:smooth_quartz
setblock ~40 ~21 ~15 minecraft:quartz_stairs[facing=south,half=top]
fill ~40 ~30 ~16 ~40 ~32 ~17 minecraft:smooth_quartz
setblock ~40 ~31 ~16 minecraft:chiseled_quartz_block
setblock ~40 ~33 ~16 minecraft:smooth_quartz
setblock ~40 ~33 ~17 minecraft:smooth_quartz
setblock ~40 ~33 ~15 minecraft:quartz_stairs[facing=south,half=top]
setblock ~40 ~34 ~16 minecraft:quartz_slab[type=bottom]
setblock ~40 ~6 ~16 minecraft:diorite_wall
setblock ~40 ~7 ~16 minecraft:quartz_slab[type=bottom]
fill ~39 ~0 ~16 ~39 ~4 ~17 minecraft:smooth_quartz
fill ~39 ~2 ~16 ~39 ~3 ~16 minecraft:chiseled_quartz_block
setblock ~39 ~5 ~16 minecraft:smooth_quartz
setblock ~39 ~5 ~17 minecraft:smooth_quartz
setblock ~39 ~5 ~15 minecraft:quartz_stairs[facing=south,half=top]
fill ~39 ~15 ~16 ~39 ~17 ~17 minecraft:smooth_quartz
setblock ~39 ~16 ~16 minecraft:chiseled_quartz_block
setblock ~39 ~15 ~15 minecraft:quartz_stairs[facing=south,half=bottom]
setblock ~39 ~17 ~15 minecraft:quartz_stairs[facing=south,half=top]
fill ~39 ~18 ~16 ~39 ~20 ~17 minecraft:smooth_quartz
setblock ~39 ~19 ~16 minecraft:chiseled_quartz_block
setblock ~39 ~21 ~16 minecraft:smooth_quartz
setblock ~39 ~21 ~17 minecraft:smooth_quartz
setblock ~39 ~21 ~15 minecraft:quartz_stairs[facing=south,half=top]
fill ~39 ~30 ~16 ~39 ~32 ~17 minecraft:smooth_quartz
setblock ~39 ~31 ~16 minecraft:chiseled_quartz_block
setblock ~39 ~33 ~16 minecraft:smooth_quartz
setblock ~39 ~33 ~17 minecraft:smooth_quartz
setblock ~39 ~33 ~15 minecraft:quartz_stairs[facing=south,half=top]
setblock ~39 ~34 ~16 minecraft:quartz_slab[type=bottom]
setblock ~39 ~6 ~16 minecraft:diorite_wall
setblock ~39 ~7 ~16 minecraft:quartz_slab[type=bottom]
fill ~38 ~0 ~16 ~38 ~4 ~17 minecraft:smooth_quartz
fill ~38 ~2 ~16 ~38 ~3 ~16 minecraft:chiseled_quartz_block
setblock ~38 ~5 ~16 minecraft:smooth_quartz
setblock ~38 ~5 ~17 minecraft:smooth_quartz
setblock ~38 ~5 ~15 minecraft:quartz_stairs[facing=south,half=top]
fill ~38 ~15 ~16 ~38 ~17 ~17 minecraft:smooth_quartz
setblock ~38 ~16 ~16 minecraft:chiseled_quartz_block
setblock ~38 ~15 ~15 minecraft:quartz_stairs[facing=south,half=bottom]
setblock ~38 ~17 ~15 minecraft:quartz_stairs[facing=south,half=top]
fill ~38 ~18 ~16 ~38 ~20 ~17 minecraft:smooth_quartz
setblock ~38 ~19 ~16 minecraft:chiseled_quartz_block
setblock ~38 ~21 ~16 minecraft:smooth_quartz
setblock ~38 ~21 ~17 minecraft:smooth_quartz
setblock ~38 ~21 ~15 minecraft:quartz_stairs[facing=south,half=top]
fill ~38 ~30 ~16 ~38 ~32 ~17 minecraft:smooth_quartz
setblock ~38 ~31 ~16 minecraft:chiseled_quartz_block
setblock ~38 ~33 ~16 minecraft:smooth_quartz
setblock ~38 ~33 ~17 minecraft:smooth_quartz
setblock ~38 ~33 ~15 minecraft:quartz_stairs[facing=south,half=top]
setblock ~38 ~34 ~16 minecraft:quartz_slab[type=bottom]
setblock ~38 ~6 ~16 minecraft:diorite_wall
setblock ~38 ~7 ~16 minecraft:quartz_slab[type=bottom]
fill ~37 ~0 ~17 ~37 ~4 ~18 minecraft:smooth_quartz
fill ~37 ~2 ~17 ~37 ~3 ~17 minecraft:chiseled_quartz_block
setblock ~37 ~5 ~17 minecraft:smooth_quartz
setblock ~37 ~5 ~18 minecraft:smooth_quartz
setblock ~37 ~5 ~16 minecraft:quartz_stairs[facing=south,half=top]
fill ~37 ~15 ~17 ~37 ~17 ~18 minecraft:smooth_quartz
setblock ~37 ~16 ~17 minecraft:chiseled_quartz_block
setblock ~37 ~15 ~16 minecraft:quartz_stairs[facing=south,half=bottom]
setblock ~37 ~17 ~16 minecraft:quartz_stairs[facing=south,half=top]
fill ~37 ~18 ~17 ~37 ~20 ~18 minecraft:smooth_quartz
setblock ~37 ~19 ~17 minecraft:chiseled_quartz_block
setblock ~37 ~21 ~17 minecraft:smooth_quartz
setblock ~37 ~21 ~18 minecraft:smooth_quartz
setblock ~37 ~21 ~16 minecraft:quartz_stairs[facing=south,half=top]
fill ~37 ~30 ~17 ~37 ~32 ~18 minecraft:smooth_quartz
setblock ~37 ~31 ~17 minecraft:chiseled_quartz_block
setblock ~37 ~33 ~17 minecraft:smooth_quartz
setblock ~37 ~33 ~18 minecraft:smooth_quartz
setblock ~37 ~33 ~16 minecraft:quartz_stairs[facing=south,half=top]
setblock ~37 ~34 ~17 minecraft:quartz_slab[type=bottom]
fill ~36 ~0 ~17 ~36 ~4 ~18 minecraft:smooth_quartz
fill ~36 ~2 ~17 ~36 ~3 ~17 minecraft:chiseled_quartz_block
setblock ~36 ~5 ~17 minecraft:smooth_quartz
setblock ~36 ~5 ~18 minecraft:smooth_quartz
setblock ~36 ~5 ~16 minecraft:quartz_stairs[facing=south,half=top]
fill ~36 ~15 ~17 ~36 ~17 ~18 minecraft:smooth_quartz
setblock ~36 ~16 ~17 minecraft:chiseled_quartz_block
setblock ~36 ~15 ~16 minecraft:quartz_stairs[facing=south,half=bottom]
setblock ~36 ~17 ~16 minecraft:quartz_stairs[facing=south,half=top]
fill ~36 ~18 ~17 ~36 ~20 ~18 minecraft:smooth_quartz
setblock ~36 ~19 ~17 minecraft:chiseled_quartz_block
setblock ~36 ~21 ~17 minecraft:smooth_quartz
setblock ~36 ~21 ~18 minecraft:smooth_quartz
setblock ~36 ~21 ~16 minecraft:quartz_stairs[facing=south,half=top]
fill ~36 ~30 ~17 ~36 ~32 ~18 minecraft:smooth_quartz
setblock ~36 ~31 ~17 minecraft:chiseled_quartz_block
setblock ~36 ~33 ~17 minecraft:smooth_quartz
setblock ~36 ~33 ~18 minecraft:smooth_quartz
setblock ~36 ~33 ~16 minecraft:quartz_stairs[facing=south,half=top]
setblock ~36 ~34 ~17 minecraft:quartz_slab[type=bottom]
fill ~35 ~0 ~18 ~35 ~4 ~19 minecraft:smooth_quartz
fill ~35 ~2 ~18 ~35 ~3 ~18 minecraft:chiseled_quartz_block
setblock ~35 ~5 ~18 minecraft:smooth_quartz
setblock ~35 ~5 ~19 minecraft:smooth_quartz
setblock ~35 ~5 ~17 minecraft:quartz_stairs[facing=south,half=top]
fill ~35 ~15 ~18 ~35 ~17 ~19 minecraft:smooth_quartz
setblock ~35 ~16 ~18 minecraft:chiseled_quartz_block
setblock ~35 ~15 ~17 minecraft:quartz_stairs[facing=south,half=bottom]
setblock ~35 ~17 ~17 minecraft:quartz_stairs[facing=south,half=top]
fill ~35 ~18 ~18 ~35 ~20 ~19 minecraft:smooth_quartz
setblock ~35 ~19 ~18 minecraft:chiseled_quartz_block
setblock ~35 ~21 ~18 minecraft:smooth_quartz
setblock ~35 ~21 ~19 minecraft:smooth_quartz
setblock ~35 ~21 ~17 minecraft:quartz_stairs[facing=south,half=top]
fill ~35 ~30 ~18 ~35 ~32 ~19 minecraft:smooth_quartz
setblock ~35 ~31 ~18 minecraft:chiseled_quartz_block
setblock ~35 ~33 ~18 minecraft:smooth_quartz
setblock ~35 ~33 ~19 minecraft:smooth_quartz
setblock ~35 ~33 ~17 minecraft:quartz_stairs[facing=south,half=top]
setblock ~35 ~34 ~18 minecraft:quartz_slab[type=bottom]
setblock ~35 ~6 ~18 minecraft:diorite_wall
setblock ~35 ~7 ~18 minecraft:quartz_slab[type=bottom]
fill ~34 ~0 ~18 ~34 ~4 ~19 minecraft:smooth_quartz
fill ~34 ~2 ~18 ~34 ~3 ~18 minecraft:chiseled_quartz_block
setblock ~34 ~5 ~18 minecraft:smooth_quartz
setblock ~34 ~5 ~19 minecraft:smooth_quartz
setblock ~34 ~5 ~17 minecraft:quartz_stairs[facing=south,half=top]
fill ~34 ~15 ~18 ~34 ~17 ~19 minecraft:smooth_quartz
setblock ~34 ~16 ~18 minecraft:chiseled_quartz_block
setblock ~34 ~15 ~17 minecraft:quartz_stairs[facing=south,half=bottom]
setblock ~34 ~17 ~17 minecraft:quartz_stairs[facing=south,half=top]
fill ~34 ~18 ~18 ~34 ~20 ~19 minecraft:smooth_quartz
setblock ~34 ~19 ~18 minecraft:chiseled_quartz_block
setblock ~34 ~21 ~18 minecraft:smooth_quartz
setblock ~34 ~21 ~19 minecraft:smooth_quartz
setblock ~34 ~21 ~17 minecraft:quartz_stairs[facing=south,half=top]
fill ~34 ~30 ~18 ~34 ~32 ~19 minecraft:smooth_quartz
setblock ~34 ~31 ~18 minecraft:chiseled_quartz_block
setblock ~34 ~33 ~18 minecraft:smooth_quartz
setblock ~34 ~33 ~19 minecraft:smooth_quartz
setblock ~34 ~33 ~17 minecraft:quartz_stairs[facing=south,half=top]
setblock ~34 ~34 ~18 minecraft:quartz_slab[type=bottom]
setblock ~34 ~6 ~18 minecraft:diorite_wall
setblock ~34 ~7 ~18 minecraft:quartz_slab[type=bottom]
fill ~33 ~0 ~19 ~33 ~4 ~20 minecraft:smooth_quartz
fill ~33 ~2 ~19 ~33 ~3 ~19 minecraft:chiseled_quartz_block
setblock ~33 ~5 ~19 minecraft:smooth_quartz
setblock ~33 ~5 ~20 minecraft:smooth_quartz
setblock ~33 ~5 ~18 minecraft:quartz_stairs[facing=south,half=top]
fill ~33 ~15 ~19 ~33 ~17 ~20 minecraft:smooth_quartz
setblock ~33 ~16 ~19 minecraft:chiseled_quartz_block
setblock ~33 ~15 ~18 minecraft:quartz_stairs[facing=south,half=bottom]
setblock ~33 ~17 ~18 minecraft:quartz_stairs[facing=south,half=top]
fill ~33 ~18 ~19 ~33 ~20 ~20 minecraft:smooth_quartz
setblock ~33 ~19 ~19 minecraft:chiseled_quartz_block
setblock ~33 ~21 ~19 minecraft:smooth_quartz
setblock ~33 ~21 ~20 minecraft:smooth_quartz
setblock ~33 ~21 ~18 minecraft:quartz_stairs[facing=south,half=top]
fill ~33 ~30 ~19 ~33 ~32 ~20 minecraft:smooth_quartz
setblock ~33 ~31 ~19 minecraft:chiseled_quartz_block
setblock ~33 ~33 ~19 minecraft:smooth_quartz
setblock ~33 ~33 ~20 minecraft:smooth_quartz
setblock ~33 ~33 ~18 minecraft:quartz_stairs[facing=south,half=top]
setblock ~33 ~34 ~19 minecraft:quartz_slab[type=bottom]
setblock ~33 ~6 ~19 minecraft:diorite_wall
setblock ~33 ~7 ~19 minecraft:quartz_slab[type=bottom]
fill ~32 ~0 ~20 ~32 ~4 ~21 minecraft:smooth_quartz
fill ~32 ~2 ~20 ~32 ~3 ~20 minecraft:chiseled_quartz_block
setblock ~32 ~5 ~20 minecraft:smooth_quartz
setblock ~32 ~5 ~21 minecraft:smooth_quartz
setblock ~32 ~5 ~19 minecraft:quartz_stairs[facing=south,half=top]
fill ~32 ~15 ~20 ~32 ~17 ~21 minecraft:smooth_quartz
setblock ~32 ~16 ~20 minecraft:chiseled_quartz_block
setblock ~32 ~15 ~19 minecraft:quartz_stairs[facing=south,half=bottom]
setblock ~32 ~17 ~19 minecraft:quartz_stairs[facing=south,half=top]
fill ~32 ~18 ~20 ~32 ~20 ~21 minecraft:smooth_quartz
setblock ~32 ~19 ~20 minecraft:chiseled_quartz_block
setblock ~32 ~21 ~20 minecraft:smooth_quartz
setblock ~32 ~21 ~21 minecraft:smooth_quartz
setblock ~32 ~21 ~19 minecraft:quartz_stairs[facing=south,half=top]
fill ~32 ~30 ~20 ~32 ~32 ~21 minecraft:smooth_quartz
setblock ~32 ~31 ~20 minecraft:chiseled_quartz_block
setblock ~32 ~33 ~20 minecraft:smooth_quartz
setblock ~32 ~33 ~21 minecraft:smooth_quartz
setblock ~32 ~33 ~19 minecraft:quartz_stairs[facing=south,half=top]
setblock ~32 ~34 ~20 minecraft:quartz_slab[type=bottom]
setblock ~32 ~6 ~20 minecraft:diorite_wall
setblock ~32 ~7 ~20 minecraft:quartz_slab[type=bottom]
fill ~31 ~0 ~21 ~31 ~4 ~22 minecraft:smooth_quartz
fill ~31 ~2 ~21 ~31 ~3 ~21 minecraft:chiseled_quartz_block
setblock ~31 ~5 ~21 minecraft:smooth_quartz
setblock ~31 ~5 ~22 minecraft:smooth_quartz
setblock ~31 ~5 ~20 minecraft:quartz_stairs[facing=south,half=top]
fill ~31 ~15 ~21 ~31 ~17 ~22 minecraft:smooth_quartz
setblock ~31 ~16 ~21 minecraft:chiseled_quartz_block
setblock ~31 ~15 ~20 minecraft:quartz_stairs[facing=south,half=bottom]
setblock ~31 ~17 ~20 minecraft:quartz_stairs[facing=south,half=top]
fill ~31 ~18 ~21 ~31 ~20 ~22 minecraft:smooth_quartz
setblock ~31 ~19 ~21 minecraft:chiseled_quartz_block
setblock ~31 ~21 ~21 minecraft:smooth_quartz
setblock ~31 ~21 ~22 minecraft:smooth_quartz
setblock ~31 ~21 ~20 minecraft:quartz_stairs[facing=south,half=top]
fill ~31 ~30 ~21 ~31 ~32 ~22 minecraft:smooth_quartz
setblock ~31 ~31 ~21 minecraft:chiseled_quartz_block
setblock ~31 ~33 ~21 minecraft:smooth_quartz
setblock ~31 ~33 ~22 minecraft:smooth_quartz
setblock ~31 ~33 ~20 minecraft:quartz_stairs[facing=south,half=top]
setblock ~31 ~34 ~21 minecraft:quartz_slab[type=bottom]
setblock ~31 ~6 ~21 minecraft:diorite_wall
setblock ~31 ~7 ~21 minecraft:quartz_slab[type=bottom]
fill ~30 ~0 ~22 ~30 ~4 ~23 minecraft:smooth_quartz
fill ~30 ~2 ~22 ~30 ~3 ~22 minecraft:chiseled_quartz_block
setblock ~30 ~5 ~22 minecraft:smooth_quartz
setblock ~30 ~5 ~23 minecraft:smooth_quartz
setblock ~30 ~5 ~21 minecraft:quartz_stairs[facing=south,half=top]
fill ~30 ~15 ~22 ~30 ~17 ~23 minecraft:smooth_quartz
setblock ~30 ~16 ~22 minecraft:chiseled_quartz_block
setblock ~30 ~15 ~21 minecraft:quartz_stairs[facing=south,half=bottom]
setblock ~30 ~17 ~21 minecraft:quartz_stairs[facing=south,half=top]
fill ~30 ~18 ~22 ~30 ~20 ~23 minecraft:smooth_quartz
setblock ~30 ~19 ~22 minecraft:chiseled_quartz_block
setblock ~30 ~21 ~22 minecraft:smooth_quartz
setblock ~30 ~21 ~23 minecraft:smooth_quartz
setblock ~30 ~21 ~21 minecraft:quartz_stairs[facing=south,half=top]
fill ~30 ~30 ~22 ~30 ~32 ~23 minecraft:smooth_quartz
setblock ~30 ~31 ~22 minecraft:chiseled_quartz_block
setblock ~30 ~33 ~22 minecraft:smooth_quartz
setblock ~30 ~33 ~23 minecraft:smooth_quartz
setblock ~30 ~33 ~21 minecraft:quartz_stairs[facing=south,half=top]
setblock ~30 ~34 ~22 minecraft:quartz_slab[type=bottom]
setblock ~30 ~6 ~22 minecraft:diorite_wall
setblock ~30 ~7 ~22 minecraft:quartz_slab[type=bottom]
fill ~29 ~0 ~23 ~29 ~4 ~24 minecraft:smooth_quartz
fill ~29 ~2 ~23 ~29 ~3 ~23 minecraft:chiseled_quartz_block
setblock ~29 ~5 ~23 minecraft:smooth_quartz
setblock ~29 ~5 ~24 minecraft:smooth_quartz
setblock ~29 ~5 ~22 minecraft:quartz_stairs[facing=south,half=top]
fill ~29 ~15 ~23 ~29 ~17 ~24 minecraft:smooth_quartz
setblock ~29 ~16 ~23 minecraft:chiseled_quartz_block
setblock ~29 ~15 ~22 minecraft:quartz_stairs[facing=south,half=bottom]
setblock ~29 ~17 ~22 minecraft:quartz_stairs[facing=south,half=top]
fill ~29 ~18 ~23 ~29 ~20 ~24 minecraft:smooth_quartz
setblock ~29 ~19 ~23 minecraft:chiseled_quartz_block
setblock ~29 ~21 ~23 minecraft:smooth_quartz
setblock ~29 ~21 ~24 minecraft:smooth_quartz
setblock ~29 ~21 ~22 minecraft:quartz_stairs[facing=south,half=top]
fill ~29 ~30 ~23 ~29 ~32 ~24 minecraft:smooth_quartz
setblock ~29 ~31 ~23 minecraft:chiseled_quartz_block
setblock ~29 ~33 ~23 minecraft:smooth_quartz
setblock ~29 ~33 ~24 minecraft:smooth_quartz
setblock ~29 ~33 ~22 minecraft:quartz_stairs[facing=south,half=top]
setblock ~29 ~34 ~23 minecraft:quartz_slab[type=bottom]
setblock ~29 ~6 ~23 minecraft:diorite_wall
setblock ~29 ~7 ~23 minecraft:quartz_slab[type=bottom]
fill ~28 ~0 ~24 ~28 ~4 ~25 minecraft:smooth_quartz
fill ~28 ~2 ~24 ~28 ~3 ~24 minecraft:chiseled_quartz_block
setblock ~28 ~5 ~24 minecraft:smooth_quartz
setblock ~28 ~5 ~25 minecraft:smooth_quartz
setblock ~28 ~5 ~23 minecraft:quartz_stairs[facing=south,half=top]
fill ~28 ~15 ~24 ~28 ~17 ~25 minecraft:smooth_quartz
setblock ~28 ~16 ~24 minecraft:chiseled_quartz_block
setblock ~28 ~15 ~23 minecraft:quartz_stairs[facing=south,half=bottom]
setblock ~28 ~17 ~23 minecraft:quartz_stairs[facing=south,half=top]
fill ~28 ~18 ~24 ~28 ~20 ~25 minecraft:smooth_quartz
setblock ~28 ~19 ~24 minecraft:chiseled_quartz_block
setblock ~28 ~21 ~24 minecraft:smooth_quartz
setblock ~28 ~21 ~25 minecraft:smooth_quartz
setblock ~28 ~21 ~23 minecraft:quartz_stairs[facing=south,half=top]
fill ~28 ~30 ~24 ~28 ~32 ~25 minecraft:smooth_quartz
setblock ~28 ~31 ~24 minecraft:chiseled_quartz_block
setblock ~28 ~33 ~24 minecraft:smooth_quartz
setblock ~28 ~33 ~25 minecraft:smooth_quartz
setblock ~28 ~33 ~23 minecraft:quartz_stairs[facing=south,half=top]
setblock ~28 ~34 ~24 minecraft:quartz_slab[type=bottom]
fill ~27 ~0 ~26 ~27 ~4 ~27 minecraft:smooth_quartz
fill ~27 ~2 ~26 ~27 ~3 ~26 minecraft:chiseled_quartz_block
setblock ~27 ~5 ~26 minecraft:smooth_quartz
setblock ~27 ~5 ~27 minecraft:smooth_quartz
setblock ~27 ~5 ~25 minecraft:quartz_stairs[facing=south,half=top]
fill ~27 ~15 ~26 ~27 ~17 ~27 minecraft:smooth_quartz
setblock ~27 ~16 ~26 minecraft:chiseled_quartz_block
setblock ~27 ~15 ~25 minecraft:quartz_stairs[facing=south,half=bottom]
setblock ~27 ~17 ~25 minecraft:quartz_stairs[facing=south,half=top]
fill ~27 ~18 ~26 ~27 ~20 ~27 minecraft:smooth_quartz
setblock ~27 ~19 ~26 minecraft:chiseled_quartz_block
setblock ~27 ~21 ~26 minecraft:smooth_quartz
setblock ~27 ~21 ~27 minecraft:smooth_quartz
setblock ~27 ~21 ~25 minecraft:quartz_stairs[facing=south,half=top]
fill ~27 ~30 ~26 ~27 ~32 ~27 minecraft:smooth_quartz
setblock ~27 ~31 ~26 minecraft:chiseled_quartz_block
setblock ~27 ~33 ~26 minecraft:smooth_quartz
setblock ~27 ~33 ~27 minecraft:smooth_quartz
setblock ~27 ~33 ~25 minecraft:quartz_stairs[facing=south,half=top]
setblock ~27 ~34 ~26 minecraft:quartz_slab[type=bottom]
fill ~63 ~6 ~24 ~64 ~7 ~25 minecraft:chiseled_quartz_block
fill ~63 ~8 ~24 ~64 ~12 ~25 minecraft:quartz_pillar[axis=y]
fill ~63 ~13 ~24 ~64 ~14 ~25 minecraft:chiseled_quartz_block
setblock ~65 ~14 ~24 minecraft:quartz_stairs[facing=south,half=top]
setblock ~62 ~14 ~24 minecraft:quartz_stairs[facing=south,half=top]
setblock ~64 ~14 ~23 minecraft:quartz_stairs[facing=south,half=top]
setblock ~63 ~14 ~23 minecraft:quartz_stairs[facing=south,half=top]
fill ~63 ~22 ~24 ~64 ~23 ~25 minecraft:chiseled_quartz_block
fill ~63 ~24 ~24 ~64 ~27 ~25 minecraft:quartz_pillar[axis=y]
fill ~63 ~28 ~24 ~64 ~29 ~25 minecraft:chiseled_quartz_block
setblock ~65 ~29 ~24 minecraft:quartz_stairs[facing=south,half=top]
setblock ~62 ~29 ~24 minecraft:quartz_stairs[facing=south,half=top]
setblock ~64 ~29 ~23 minecraft:quartz_stairs[facing=south,half=top]
setblock ~63 ~29 ~23 minecraft:quartz_stairs[facing=south,half=top]
fill ~54 ~6 ~17 ~55 ~7 ~18 minecraft:chiseled_quartz_block
fill ~54 ~8 ~17 ~55 ~12 ~18 minecraft:quartz_pillar[axis=y]
fill ~54 ~13 ~17 ~55 ~14 ~18 minecraft:chiseled_quartz_block
setblock ~56 ~14 ~17 minecraft:quartz_stairs[facing=south,half=top]
setblock ~53 ~14 ~17 minecraft:quartz_stairs[facing=south,half=top]
setblock ~55 ~14 ~16 minecraft:quartz_stairs[facing=south,half=top]
setblock ~54 ~14 ~16 minecraft:quartz_stairs[facing=south,half=top]
fill ~54 ~22 ~17 ~55 ~23 ~18 minecraft:chiseled_quartz_block
fill ~54 ~24 ~17 ~55 ~27 ~18 minecraft:quartz_pillar[axis=y]
fill ~54 ~28 ~17 ~55 ~29 ~18 minecraft:chiseled_quartz_block
setblock ~56 ~29 ~17 minecraft:quartz_stairs[facing=south,half=top]
setblock ~53 ~29 ~17 minecraft:quartz_stairs[facing=south,half=top]
setblock ~55 ~29 ~16 minecraft:quartz_stairs[facing=south,half=top]
setblock ~54 ~29 ~16 minecraft:quartz_stairs[facing=south,half=top]
fill ~45 ~6 ~15 ~46 ~7 ~16 minecraft:chiseled_quartz_block
fill ~45 ~8 ~15 ~46 ~12 ~16 minecraft:quartz_pillar[axis=y]
fill ~45 ~13 ~15 ~46 ~14 ~16 minecraft:chiseled_quartz_block
setblock ~47 ~14 ~15 minecraft:quartz_stairs[facing=south,half=top]
setblock ~44 ~14 ~15 minecraft:quartz_stairs[facing=south,half=top]
setblock ~46 ~14 ~14 minecraft:quartz_stairs[facing=south,half=top]
setblock ~45 ~14 ~14 minecraft:quartz_stairs[facing=south,half=top]
fill ~45 ~22 ~15 ~46 ~23 ~16 minecraft:chiseled_quartz_block
fill ~45 ~24 ~15 ~46 ~27 ~16 minecraft:quartz_pillar[axis=y]
fill ~45 ~28 ~15 ~46 ~29 ~16 minecraft:chiseled_quartz_block
setblock ~47 ~29 ~15 minecraft:quartz_stairs[facing=south,half=top]
setblock ~44 ~29 ~15 minecraft:quartz_stairs[facing=south,half=top]
setblock ~46 ~29 ~14 minecraft:quartz_stairs[facing=south,half=top]
setblock ~45 ~29 ~14 minecraft:quartz_stairs[facing=south,half=top]
fill ~36 ~6 ~17 ~37 ~7 ~18 minecraft:chiseled_quartz_block
fill ~36 ~8 ~17 ~37 ~12 ~18 minecraft:quartz_pillar[axis=y]
fill ~36 ~13 ~17 ~37 ~14 ~18 minecraft:chiseled_quartz_block
setblock ~38 ~14 ~17 minecraft:quartz_stairs[facing=south,half=top]
setblock ~35 ~14 ~17 minecraft:quartz_stairs[facing=south,half=top]
setblock ~37 ~14 ~16 minecraft:quartz_stairs[facing=south,half=top]
setblock ~36 ~14 ~16 minecraft:quartz_stairs[facing=south,half=top]
fill ~36 ~22 ~17 ~37 ~23 ~18 minecraft:chiseled_quartz_block
fill ~36 ~24 ~17 ~37 ~27 ~18 minecraft:quartz_pillar[axis=y]
fill ~36 ~28 ~17 ~37 ~29 ~18 minecraft:chiseled_quartz_block
setblock ~38 ~29 ~17 minecraft:quartz_stairs[facing=south,half=top]
setblock ~35 ~29 ~17 minecraft:quartz_stairs[facing=south,half=top]
setblock ~37 ~29 ~16 minecraft:quartz_stairs[facing=south,half=top]
setblock ~36 ~29 ~16 minecraft:quartz_stairs[facing=south,half=top]
fill ~27 ~6 ~24 ~28 ~7 ~25 minecraft:chiseled_quartz_block
fill ~27 ~8 ~24 ~28 ~12 ~25 minecraft:quartz_pillar[axis=y]
fill ~27 ~13 ~24 ~28 ~14 ~25 minecraft:chiseled_quartz_block
setblock ~29 ~14 ~24 minecraft:quartz_stairs[facing=south,half=top]
setblock ~26 ~14 ~24 minecraft:quartz_stairs[facing=south,half=top]
setblock ~28 ~14 ~23 minecraft:quartz_stairs[facing=south,half=top]
setblock ~27 ~14 ~23 minecraft:quartz_stairs[facing=south,half=top]
fill ~27 ~22 ~24 ~28 ~23 ~25 minecraft:chiseled_quartz_block
fill ~27 ~24 ~24 ~28 ~27 ~25 minecraft:quartz_pillar[axis=y]
fill ~27 ~28 ~24 ~28 ~29 ~25 minecraft:chiseled_quartz_block
setblock ~29 ~29 ~24 minecraft:quartz_stairs[facing=south,half=top]
setblock ~26 ~29 ~24 minecraft:quartz_stairs[facing=south,half=top]
setblock ~28 ~29 ~23 minecraft:quartz_stairs[facing=south,half=top]
setblock ~27 ~29 ~23 minecraft:quartz_stairs[facing=south,half=top]
fill ~64 ~35 ~26 ~64 ~36 ~26 minecraft:chiseled_quartz_block
setblock ~64 ~37 ~26 minecraft:quartz_slab[type=bottom]
fill ~27 ~35 ~26 ~27 ~36 ~26 minecraft:chiseled_quartz_block
setblock ~27 ~37 ~26 minecraft:quartz_slab[type=bottom]
fill ~63 ~5 ~26 ~63 ~5 ~26 minecraft:polished_blackstone
fill ~63 ~17 ~26 ~63 ~17 ~26 minecraft:polished_blackstone
fill ~62 ~5 ~25 ~62 ~5 ~26 minecraft:polished_blackstone
fill ~62 ~17 ~25 ~62 ~17 ~26 minecraft:polished_blackstone
fill ~61 ~5 ~24 ~61 ~5 ~26 minecraft:polished_blackstone
fill ~61 ~17 ~24 ~61 ~17 ~26 minecraft:polished_blackstone
fill ~60 ~5 ~23 ~60 ~5 ~26 minecraft:polished_blackstone
fill ~60 ~17 ~23 ~60 ~17 ~26 minecraft:polished_blackstone
fill ~59 ~5 ~22 ~59 ~5 ~26 minecraft:polished_blackstone
fill ~59 ~17 ~22 ~59 ~17 ~26 minecraft:polished_blackstone
fill ~58 ~5 ~21 ~58 ~5 ~26 minecraft:polished_blackstone
fill ~58 ~17 ~21 ~58 ~17 ~26 minecraft:polished_blackstone
fill ~57 ~5 ~20 ~57 ~5 ~26 minecraft:polished_blackstone
fill ~57 ~17 ~20 ~57 ~17 ~26 minecraft:polished_blackstone
fill ~56 ~5 ~20 ~56 ~5 ~26 minecraft:polished_blackstone
fill ~56 ~17 ~20 ~56 ~17 ~26 minecraft:polished_blackstone
fill ~55 ~5 ~19 ~55 ~5 ~26 minecraft:polished_blackstone
fill ~55 ~17 ~19 ~55 ~17 ~26 minecraft:polished_blackstone
fill ~54 ~5 ~19 ~54 ~5 ~26 minecraft:polished_blackstone
fill ~54 ~17 ~19 ~54 ~17 ~26 minecraft:polished_blackstone
fill ~53 ~5 ~18 ~53 ~5 ~26 minecraft:polished_blackstone
fill ~53 ~17 ~18 ~53 ~17 ~26 minecraft:polished_blackstone
fill ~52 ~5 ~18 ~52 ~5 ~26 minecraft:polished_blackstone
fill ~52 ~17 ~18 ~52 ~17 ~26 minecraft:polished_blackstone
fill ~51 ~5 ~18 ~51 ~5 ~26 minecraft:polished_blackstone
fill ~51 ~17 ~18 ~51 ~17 ~26 minecraft:polished_blackstone
fill ~50 ~5 ~17 ~50 ~5 ~26 minecraft:polished_blackstone
fill ~50 ~17 ~17 ~50 ~17 ~26 minecraft:polished_blackstone
fill ~49 ~5 ~17 ~49 ~5 ~26 minecraft:polished_blackstone
fill ~49 ~17 ~17 ~49 ~17 ~26 minecraft:polished_blackstone
fill ~48 ~5 ~17 ~48 ~5 ~26 minecraft:polished_blackstone
fill ~48 ~17 ~17 ~48 ~17 ~26 minecraft:polished_blackstone
fill ~47 ~5 ~17 ~47 ~5 ~26 minecraft:polished_blackstone
fill ~47 ~17 ~17 ~47 ~17 ~26 minecraft:polished_blackstone
fill ~46 ~5 ~17 ~46 ~5 ~26 minecraft:polished_blackstone
fill ~46 ~17 ~17 ~46 ~17 ~26 minecraft:polished_blackstone
fill ~45 ~5 ~17 ~45 ~5 ~26 minecraft:polished_blackstone
fill ~45 ~17 ~17 ~45 ~17 ~26 minecraft:polished_blackstone
fill ~44 ~5 ~17 ~44 ~5 ~26 minecraft:polished_blackstone
fill ~44 ~17 ~17 ~44 ~17 ~26 minecraft:polished_blackstone
fill ~43 ~5 ~17 ~43 ~5 ~26 minecraft:polished_blackstone
fill ~43 ~17 ~17 ~43 ~17 ~26 minecraft:polished_blackstone
fill ~42 ~5 ~17 ~42 ~5 ~26 minecraft:polished_blackstone
fill ~42 ~17 ~17 ~42 ~17 ~26 minecraft:polished_blackstone
fill ~41 ~5 ~17 ~41 ~5 ~26 minecraft:polished_blackstone
fill ~41 ~17 ~17 ~41 ~17 ~26 minecraft:polished_blackstone
fill ~40 ~5 ~18 ~40 ~5 ~26 minecraft:polished_blackstone
fill ~40 ~17 ~18 ~40 ~17 ~26 minecraft:polished_blackstone
fill ~39 ~5 ~18 ~39 ~5 ~26 minecraft:polished_blackstone
fill ~39 ~17 ~18 ~39 ~17 ~26 minecraft:polished_blackstone
fill ~38 ~5 ~18 ~38 ~5 ~26 minecraft:polished_blackstone
fill ~38 ~17 ~18 ~38 ~17 ~26 minecraft:polished_blackstone
fill ~37 ~5 ~19 ~37 ~5 ~26 minecraft:polished_blackstone
fill ~37 ~17 ~19 ~37 ~17 ~26 minecraft:polished_blackstone
fill ~36 ~5 ~19 ~36 ~5 ~26 minecraft:polished_blackstone
fill ~36 ~17 ~19 ~36 ~17 ~26 minecraft:polished_blackstone
fill ~35 ~5 ~20 ~35 ~5 ~26 minecraft:polished_blackstone
fill ~35 ~17 ~20 ~35 ~17 ~26 minecraft:polished_blackstone
fill ~34 ~5 ~20 ~34 ~5 ~26 minecraft:polished_blackstone
fill ~34 ~17 ~20 ~34 ~17 ~26 minecraft:polished_blackstone
fill ~33 ~5 ~21 ~33 ~5 ~26 minecraft:polished_blackstone
fill ~33 ~17 ~21 ~33 ~17 ~26 minecraft:polished_blackstone
fill ~32 ~5 ~22 ~32 ~5 ~26 minecraft:polished_blackstone
fill ~32 ~17 ~22 ~32 ~17 ~26 minecraft:polished_blackstone
fill ~31 ~5 ~23 ~31 ~5 ~26 minecraft:polished_blackstone
fill ~31 ~17 ~23 ~31 ~17 ~26 minecraft:polished_blackstone
fill ~30 ~5 ~24 ~30 ~5 ~26 minecraft:polished_blackstone
fill ~30 ~17 ~24 ~30 ~17 ~26 minecraft:polished_blackstone
fill ~29 ~5 ~25 ~29 ~5 ~26 minecraft:polished_blackstone
fill ~29 ~17 ~25 ~29 ~17 ~26 minecraft:polished_blackstone
fill ~28 ~5 ~26 ~28 ~5 ~26 minecraft:polished_blackstone
fill ~28 ~17 ~26 ~28 ~17 ~26 minecraft:polished_blackstone
fill ~27 ~0 ~27 ~64 ~34 ~27 minecraft:polished_blackstone
fill ~58 ~6 ~24 ~58 ~29 ~24 minecraft:polished_blackstone_wall
fill ~57 ~6 ~24 ~57 ~29 ~24 minecraft:polished_blackstone_wall
fill ~57 ~14 ~24 ~58 ~14 ~24 minecraft:polished_blackstone
fill ~57 ~26 ~24 ~58 ~26 ~24 minecraft:polished_blackstone
fill ~46 ~6 ~24 ~46 ~29 ~24 minecraft:polished_blackstone_wall
fill ~45 ~6 ~24 ~45 ~29 ~24 minecraft:polished_blackstone_wall
fill ~45 ~14 ~24 ~46 ~14 ~24 minecraft:polished_blackstone
fill ~45 ~26 ~24 ~46 ~26 ~24 minecraft:polished_blackstone
fill ~34 ~6 ~24 ~34 ~29 ~24 minecraft:polished_blackstone_wall
fill ~33 ~6 ~24 ~33 ~29 ~24 minecraft:polished_blackstone_wall
fill ~33 ~14 ~24 ~34 ~14 ~24 minecraft:polished_blackstone
fill ~33 ~26 ~24 ~34 ~26 ~24 minecraft:polished_blackstone
fill ~64 ~0 ~26 ~64 ~34 ~27 minecraft:smooth_quartz
