# Arco central com pilastras, brasao, querubins e cortina de fios.
# GERADO por tools/gen_castle.py; nao editar a mao.
fill ~-22 ~0 ~27 ~-14 ~35 ~35 minecraft:smooth_quartz
fill ~14 ~0 ~27 ~22 ~35 ~35 minecraft:smooth_quartz
fill ~-26 ~0 ~27 ~-23 ~35 ~35 minecraft:smooth_quartz
fill ~23 ~0 ~27 ~26 ~35 ~35 minecraft:smooth_quartz
fill ~-19 ~0 ~26 ~-17 ~2 ~26 minecraft:chiseled_quartz_block
fill ~-19 ~3 ~26 ~-17 ~30 ~26 minecraft:quartz_pillar[axis=y]
fill ~-19 ~31 ~26 ~-17 ~33 ~26 minecraft:chiseled_quartz_block
fill ~-14 ~0 ~27 ~-14 ~31 ~27 minecraft:chiseled_quartz_block
fill ~-13 ~29 ~27 ~-11 ~29 ~35 minecraft:smooth_quartz
fill ~-13 ~28 ~27 ~-12 ~28 ~35 minecraft:smooth_quartz
fill ~-13 ~27 ~27 ~-13 ~27 ~35 minecraft:smooth_quartz
fill ~17 ~0 ~26 ~19 ~2 ~26 minecraft:chiseled_quartz_block
fill ~17 ~3 ~26 ~19 ~30 ~26 minecraft:quartz_pillar[axis=y]
fill ~17 ~31 ~26 ~19 ~33 ~26 minecraft:chiseled_quartz_block
fill ~14 ~0 ~27 ~14 ~31 ~27 minecraft:chiseled_quartz_block
fill ~11 ~29 ~27 ~13 ~29 ~35 minecraft:smooth_quartz
fill ~12 ~28 ~27 ~13 ~28 ~35 minecraft:smooth_quartz
fill ~13 ~27 ~27 ~13 ~27 ~35 minecraft:smooth_quartz
fill ~-13 ~30 ~27 ~13 ~35 ~35 minecraft:smooth_quartz
fill ~-13 ~31 ~27 ~13 ~31 ~27 minecraft:chiseled_quartz_block
fill ~-12 ~30 ~31 ~12 ~30 ~35 minecraft:black_concrete
fill ~-26 ~36 ~27 ~26 ~38 ~35 minecraft:smooth_quartz
fill ~-26 ~37 ~27 ~26 ~37 ~27 minecraft:chiseled_quartz_block
fill ~-26 ~39 ~27 ~26 ~40 ~35 minecraft:smooth_quartz
fill ~-26 ~40 ~26 ~26 ~40 ~26 minecraft:quartz_stairs[facing=south,half=top]
fill ~-26 ~41 ~27 ~26 ~41 ~35 minecraft:smooth_quartz
fill ~-8 ~42 ~27 ~8 ~43 ~29 minecraft:smooth_quartz
fill ~-4 ~42 ~27 ~4 ~43 ~27 minecraft:chiseled_quartz_block
setblock ~-9 ~42 ~27 minecraft:quartz_stairs[facing=south,half=bottom]
setblock ~-10 ~42 ~27 minecraft:quartz_stairs[facing=south,half=bottom]
setblock ~9 ~42 ~27 minecraft:quartz_stairs[facing=south,half=bottom]
setblock ~10 ~42 ~27 minecraft:quartz_stairs[facing=south,half=bottom]
fill ~-3 ~44 ~27 ~3 ~49 ~28 minecraft:smooth_quartz
fill ~-2 ~45 ~27 ~2 ~48 ~27 minecraft:gold_block
fill ~-3 ~44 ~27 ~3 ~44 ~27 minecraft:chiseled_quartz_block
fill ~-3 ~49 ~27 ~3 ~49 ~27 minecraft:chiseled_quartz_block
fill ~-6 ~44 ~27 ~-5 ~47 ~28 minecraft:smooth_quartz
setblock ~-5 ~48 ~27 minecraft:chiseled_quartz_block
setblock ~-7 ~46 ~27 minecraft:quartz_stairs[facing=south,half=bottom]
setblock ~-8 ~45 ~27 minecraft:quartz_stairs[facing=south,half=bottom]
fill ~5 ~44 ~27 ~6 ~47 ~28 minecraft:smooth_quartz
setblock ~5 ~48 ~27 minecraft:chiseled_quartz_block
setblock ~7 ~46 ~27 minecraft:quartz_stairs[facing=south,half=bottom]
setblock ~8 ~45 ~27 minecraft:quartz_stairs[facing=south,half=bottom]
fill ~-1 ~50 ~27 ~1 ~50 ~27 minecraft:chiseled_quartz_block
fill ~-12 ~0 ~30 ~-12 ~28 ~30 minecraft:white_stained_glass_pane
fill ~-10 ~0 ~30 ~-10 ~28 ~30 minecraft:white_stained_glass_pane
fill ~-8 ~0 ~30 ~-8 ~28 ~30 minecraft:white_stained_glass_pane
fill ~-6 ~0 ~30 ~-6 ~28 ~30 minecraft:white_stained_glass_pane
fill ~-4 ~0 ~30 ~-4 ~28 ~30 minecraft:white_stained_glass_pane
fill ~-2 ~0 ~30 ~-2 ~28 ~30 minecraft:white_stained_glass_pane
fill ~0 ~0 ~30 ~0 ~28 ~30 minecraft:white_stained_glass_pane
fill ~2 ~0 ~30 ~2 ~28 ~30 minecraft:white_stained_glass_pane
fill ~4 ~0 ~30 ~4 ~28 ~30 minecraft:white_stained_glass_pane
fill ~6 ~0 ~30 ~6 ~28 ~30 minecraft:white_stained_glass_pane
fill ~8 ~0 ~30 ~8 ~28 ~30 minecraft:white_stained_glass_pane
fill ~10 ~0 ~30 ~10 ~28 ~30 minecraft:white_stained_glass_pane
fill ~12 ~0 ~30 ~12 ~28 ~30 minecraft:white_stained_glass_pane
fill ~-14 ~0 ~36 ~14 ~35 ~36 minecraft:black_concrete
